2025-07-21 17:46:54,308 - INFO - User found for email: aayanali1208@gmail.com
2025-07-21 17:46:55,099 - INFO - User ID found for email: aayanali1208@gmail.com
2025-07-21 17:47:28,451 - ERROR - Error fetching inventory: 1146 (42S02): Table 'test_db.products' doesn't exist
Traceback (most recent call last):
  File "C:\Users\mnarv\OneDrive\Desktop\ALL WORK\project_SQL+DB\.venv\Lib\site-packages\mysql\connector\connection_cext.py", line 772, in cmd_query
    self._cmysql.query(
    ~~~~~~~~~~~~~~~~~~^
        query,
        ^^^^^^
    ...<3 lines>...
        query_attrs=self.query_attrs,
        ^^^^^^^^^^^^^^^^^^^^^^^^^^^^^
    )
    ^
_mysql_connector.MySQLInterfaceError: Table 'test_db.products' doesn't exist

The above exception was the direct cause of the following exception:

Traceback (most recent call last):
  File "c:\Users\mnarv\OneDrive\Desktop\ALL WORK\project_SQL+DB\model\inventory_model.py", line 17, in fetch_all_inventory
            cursor.execute("""
            ~~~~~~~~~~~~~~^^^^
        SELECT
        ^^^^^^
    ...<9 lines>...
        JOIN variants v ON p.id = v.product_id
        ^^^^^^^^^^^^^^^^^^^^^^^^^^^^^^^^^^^^^^
    """)
    ^^^^
  File "C:\Users\mnarv\OneDrive\Desktop\ALL WORK\project_SQL+DB\.venv\Lib\site-packages\mysql\connector\cursor_cext.py", line 356, in execute
    self._connection.cmd_query(
    ~~~~~~~~~~~~~~~~~~~~~~~~~~^
        self._stmt_partition["mappable_stmt"],
        ^^^^^^^^^^^^^^^^^^^^^^^^^^^^^^^^^^^^^^
    ...<2 lines>...
        raw_as_string=self._raw_as_string,
        ^^^^^^^^^^^^^^^^^^^^^^^^^^^^^^^^^^
    )
    ^
  File "C:\Users\mnarv\OneDrive\Desktop\ALL WORK\project_SQL+DB\.venv\Lib\site-packages\mysql\connector\opentelemetry\context_propagation.py", line 97, in wrapper
    return method(cnx, *args, **kwargs)
  File "C:\Users\mnarv\OneDrive\Desktop\ALL WORK\project_SQL+DB\.venv\Lib\site-packages\mysql\connector\connection_cext.py", line 781, in cmd_query
    raise get_mysql_exception(
        err.errno, msg=err.msg, sqlstate=err.sqlstate
    ) from err
mysql.connector.errors.ProgrammingError: 1146 (42S02): Table 'test_db.products' doesn't exist
2025-07-21 17:50:14,915 - ERROR - Error fetching inventory: 1146 (42S02): Table 'test_db.products' doesn't exist
Traceback (most recent call last):
  File "C:\Users\mnarv\OneDrive\Desktop\ALL WORK\project_SQL+DB\.venv\Lib\site-packages\mysql\connector\connection_cext.py", line 772, in cmd_query
    self._cmysql.query(
    ~~~~~~~~~~~~~~~~~~^
        query,
        ^^^^^^
    ...<3 lines>...
        query_attrs=self.query_attrs,
        ^^^^^^^^^^^^^^^^^^^^^^^^^^^^^
    )
    ^
_mysql_connector.MySQLInterfaceError: Table 'test_db.products' doesn't exist

The above exception was the direct cause of the following exception:

Traceback (most recent call last):
  File "c:\Users\mnarv\OneDrive\Desktop\ALL WORK\project_SQL+DB\model\inventory_model.py", line 16, in fetch_all_inventory
    cursor.execute("""
    ~~~~~~~~~~~~~~^^^^
        SELECT
        ^^^^^^
    ...<9 lines>...
        JOIN variants v ON p.id = v.product_id
        ^^^^^^^^^^^^^^^^^^^^^^^^^^^^^^^^^^^^^^
    """)
    ^^^^
  File "C:\Users\mnarv\OneDrive\Desktop\ALL WORK\project_SQL+DB\.venv\Lib\site-packages\mysql\connector\cursor_cext.py", line 356, in execute
    self._connection.cmd_query(
    ~~~~~~~~~~~~~~~~~~~~~~~~~~^
        self._stmt_partition["mappable_stmt"],
        ^^^^^^^^^^^^^^^^^^^^^^^^^^^^^^^^^^^^^^
    ...<2 lines>...
        raw_as_string=self._raw_as_string,
        ^^^^^^^^^^^^^^^^^^^^^^^^^^^^^^^^^^
    )
    ^
  File "C:\Users\mnarv\OneDrive\Desktop\ALL WORK\project_SQL+DB\.venv\Lib\site-packages\mysql\connector\opentelemetry\context_propagation.py", line 97, in wrapper
    return method(cnx, *args, **kwargs)
  File "C:\Users\mnarv\OneDrive\Desktop\ALL WORK\project_SQL+DB\.venv\Lib\site-packages\mysql\connector\connection_cext.py", line 781, in cmd_query
    raise get_mysql_exception(
        err.errno, msg=err.msg, sqlstate=err.sqlstate
    ) from err
mysql.connector.errors.ProgrammingError: 1146 (42S02): Table 'test_db.products' doesn't exist
2025-07-21 17:50:16,877 - ERROR - Error fetching inventory: 1146 (42S02): Table 'test_db.products' doesn't exist
Traceback (most recent call last):
  File "C:\Users\mnarv\OneDrive\Desktop\ALL WORK\project_SQL+DB\.venv\Lib\site-packages\mysql\connector\connection_cext.py", line 772, in cmd_query
    self._cmysql.query(
    ~~~~~~~~~~~~~~~~~~^
        query,
        ^^^^^^
    ...<3 lines>...
        query_attrs=self.query_attrs,
        ^^^^^^^^^^^^^^^^^^^^^^^^^^^^^
    )
    ^
_mysql_connector.MySQLInterfaceError: Table 'test_db.products' doesn't exist

The above exception was the direct cause of the following exception:

Traceback (most recent call last):
  File "c:\Users\mnarv\OneDrive\Desktop\ALL WORK\project_SQL+DB\model\inventory_model.py", line 16, in fetch_all_inventory
    cursor.execute("""
    ~~~~~~~~~~~~~~^^^^
        SELECT
        ^^^^^^
    ...<9 lines>...
        JOIN variants v ON p.id = v.product_id
        ^^^^^^^^^^^^^^^^^^^^^^^^^^^^^^^^^^^^^^
    """)
    ^^^^
  File "C:\Users\mnarv\OneDrive\Desktop\ALL WORK\project_SQL+DB\.venv\Lib\site-packages\mysql\connector\cursor_cext.py", line 356, in execute
    self._connection.cmd_query(
    ~~~~~~~~~~~~~~~~~~~~~~~~~~^
        self._stmt_partition["mappable_stmt"],
        ^^^^^^^^^^^^^^^^^^^^^^^^^^^^^^^^^^^^^^
    ...<2 lines>...
        raw_as_string=self._raw_as_string,
        ^^^^^^^^^^^^^^^^^^^^^^^^^^^^^^^^^^
    )
    ^
  File "C:\Users\mnarv\OneDrive\Desktop\ALL WORK\project_SQL+DB\.venv\Lib\site-packages\mysql\connector\opentelemetry\context_propagation.py", line 97, in wrapper
    return method(cnx, *args, **kwargs)
  File "C:\Users\mnarv\OneDrive\Desktop\ALL WORK\project_SQL+DB\.venv\Lib\site-packages\mysql\connector\connection_cext.py", line 781, in cmd_query
    raise get_mysql_exception(
        err.errno, msg=err.msg, sqlstate=err.sqlstate
    ) from err
mysql.connector.errors.ProgrammingError: 1146 (42S02): Table 'test_db.products' doesn't exist
2025-07-21 17:50:17,984 - ERROR - Error fetching inventory: 1146 (42S02): Table 'test_db.products' doesn't exist
Traceback (most recent call last):
  File "C:\Users\mnarv\OneDrive\Desktop\ALL WORK\project_SQL+DB\.venv\Lib\site-packages\mysql\connector\connection_cext.py", line 772, in cmd_query
    self._cmysql.query(
    ~~~~~~~~~~~~~~~~~~^
        query,
        ^^^^^^
    ...<3 lines>...
        query_attrs=self.query_attrs,
        ^^^^^^^^^^^^^^^^^^^^^^^^^^^^^
    )
    ^
_mysql_connector.MySQLInterfaceError: Table 'test_db.products' doesn't exist

The above exception was the direct cause of the following exception:

Traceback (most recent call last):
  File "c:\Users\mnarv\OneDrive\Desktop\ALL WORK\project_SQL+DB\model\inventory_model.py", line 16, in fetch_all_inventory
    cursor.execute("""
    ~~~~~~~~~~~~~~^^^^
        SELECT
        ^^^^^^
    ...<9 lines>...
        JOIN variants v ON p.id = v.product_id
        ^^^^^^^^^^^^^^^^^^^^^^^^^^^^^^^^^^^^^^
    """)
    ^^^^
  File "C:\Users\mnarv\OneDrive\Desktop\ALL WORK\project_SQL+DB\.venv\Lib\site-packages\mysql\connector\cursor_cext.py", line 356, in execute
    self._connection.cmd_query(
    ~~~~~~~~~~~~~~~~~~~~~~~~~~^
        self._stmt_partition["mappable_stmt"],
        ^^^^^^^^^^^^^^^^^^^^^^^^^^^^^^^^^^^^^^
    ...<2 lines>...
        raw_as_string=self._raw_as_string,
        ^^^^^^^^^^^^^^^^^^^^^^^^^^^^^^^^^^
    )
    ^
  File "C:\Users\mnarv\OneDrive\Desktop\ALL WORK\project_SQL+DB\.venv\Lib\site-packages\mysql\connector\opentelemetry\context_propagation.py", line 97, in wrapper
    return method(cnx, *args, **kwargs)
  File "C:\Users\mnarv\OneDrive\Desktop\ALL WORK\project_SQL+DB\.venv\Lib\site-packages\mysql\connector\connection_cext.py", line 781, in cmd_query
    raise get_mysql_exception(
        err.errno, msg=err.msg, sqlstate=err.sqlstate
    ) from err
mysql.connector.errors.ProgrammingError: 1146 (42S02): Table 'test_db.products' doesn't exist
2025-07-21 17:54:29,804 - ERROR - Error fetching product list: 1146 (42S02): Table 'test_db.products' doesn't exist
Traceback (most recent call last):
  File "C:\Users\mnarv\OneDrive\Desktop\ALL WORK\project_SQL+DB\.venv\Lib\site-packages\mysql\connector\connection_cext.py", line 772, in cmd_query
    self._cmysql.query(
    ~~~~~~~~~~~~~~~~~~^
        query,
        ^^^^^^
    ...<3 lines>...
        query_attrs=self.query_attrs,
        ^^^^^^^^^^^^^^^^^^^^^^^^^^^^^
    )
    ^
_mysql_connector.MySQLInterfaceError: Table 'test_db.products' doesn't exist

The above exception was the direct cause of the following exception:

Traceback (most recent call last):
  File "c:\Users\mnarv\OneDrive\Desktop\ALL WORK\project_SQL+DB\model\inventory_model.py", line 17, in fetch_all_inventory
    cursor.execute("""
    ~~~~~~~~~~~~~~^^^^
        SELECT
        ^^^^^^
    ...<3 lines>...
        FROM products;
        ^^^^^^^^^^^^^^
    """)
    ^^^^
  File "C:\Users\mnarv\OneDrive\Desktop\ALL WORK\project_SQL+DB\.venv\Lib\site-packages\mysql\connector\cursor_cext.py", line 356, in execute
    self._connection.cmd_query(
    ~~~~~~~~~~~~~~~~~~~~~~~~~~^
        self._stmt_partition["mappable_stmt"],
        ^^^^^^^^^^^^^^^^^^^^^^^^^^^^^^^^^^^^^^
    ...<2 lines>...
        raw_as_string=self._raw_as_string,
        ^^^^^^^^^^^^^^^^^^^^^^^^^^^^^^^^^^
    )
    ^
  File "C:\Users\mnarv\OneDrive\Desktop\ALL WORK\project_SQL+DB\.venv\Lib\site-packages\mysql\connector\opentelemetry\context_propagation.py", line 97, in wrapper
    return method(cnx, *args, **kwargs)
  File "C:\Users\mnarv\OneDrive\Desktop\ALL WORK\project_SQL+DB\.venv\Lib\site-packages\mysql\connector\connection_cext.py", line 781, in cmd_query
    raise get_mysql_exception(
        err.errno, msg=err.msg, sqlstate=err.sqlstate
    ) from err
mysql.connector.errors.ProgrammingError: 1146 (42S02): Table 'test_db.products' doesn't exist
2025-07-21 17:54:31,925 - ERROR - Error fetching product list: 1146 (42S02): Table 'test_db.products' doesn't exist
Traceback (most recent call last):
  File "C:\Users\mnarv\OneDrive\Desktop\ALL WORK\project_SQL+DB\.venv\Lib\site-packages\mysql\connector\connection_cext.py", line 772, in cmd_query
    self._cmysql.query(
    ~~~~~~~~~~~~~~~~~~^
        query,
        ^^^^^^
    ...<3 lines>...
        query_attrs=self.query_attrs,
        ^^^^^^^^^^^^^^^^^^^^^^^^^^^^^
    )
    ^
_mysql_connector.MySQLInterfaceError: Table 'test_db.products' doesn't exist

The above exception was the direct cause of the following exception:

Traceback (most recent call last):
  File "c:\Users\mnarv\OneDrive\Desktop\ALL WORK\project_SQL+DB\model\inventory_model.py", line 17, in fetch_all_inventory
    cursor.execute("""
    ~~~~~~~~~~~~~~^^^^
        SELECT
        ^^^^^^
    ...<3 lines>...
        FROM products;
        ^^^^^^^^^^^^^^
    """)
    ^^^^
  File "C:\Users\mnarv\OneDrive\Desktop\ALL WORK\project_SQL+DB\.venv\Lib\site-packages\mysql\connector\cursor_cext.py", line 356, in execute
    self._connection.cmd_query(
    ~~~~~~~~~~~~~~~~~~~~~~~~~~^
        self._stmt_partition["mappable_stmt"],
        ^^^^^^^^^^^^^^^^^^^^^^^^^^^^^^^^^^^^^^
    ...<2 lines>...
        raw_as_string=self._raw_as_string,
        ^^^^^^^^^^^^^^^^^^^^^^^^^^^^^^^^^^
    )
    ^
  File "C:\Users\mnarv\OneDrive\Desktop\ALL WORK\project_SQL+DB\.venv\Lib\site-packages\mysql\connector\opentelemetry\context_propagation.py", line 97, in wrapper
    return method(cnx, *args, **kwargs)
  File "C:\Users\mnarv\OneDrive\Desktop\ALL WORK\project_SQL+DB\.venv\Lib\site-packages\mysql\connector\connection_cext.py", line 781, in cmd_query
    raise get_mysql_exception(
        err.errno, msg=err.msg, sqlstate=err.sqlstate
    ) from err
mysql.connector.errors.ProgrammingError: 1146 (42S02): Table 'test_db.products' doesn't exist
2025-07-21 17:54:32,922 - ERROR - Error fetching product list: 1146 (42S02): Table 'test_db.products' doesn't exist
Traceback (most recent call last):
  File "C:\Users\mnarv\OneDrive\Desktop\ALL WORK\project_SQL+DB\.venv\Lib\site-packages\mysql\connector\connection_cext.py", line 772, in cmd_query
    self._cmysql.query(
    ~~~~~~~~~~~~~~~~~~^
        query,
        ^^^^^^
    ...<3 lines>...
        query_attrs=self.query_attrs,
        ^^^^^^^^^^^^^^^^^^^^^^^^^^^^^
    )
    ^
_mysql_connector.MySQLInterfaceError: Table 'test_db.products' doesn't exist

The above exception was the direct cause of the following exception:

Traceback (most recent call last):
  File "c:\Users\mnarv\OneDrive\Desktop\ALL WORK\project_SQL+DB\model\inventory_model.py", line 17, in fetch_all_inventory
    cursor.execute("""
    ~~~~~~~~~~~~~~^^^^
        SELECT
        ^^^^^^
    ...<3 lines>...
        FROM products;
        ^^^^^^^^^^^^^^
    """)
    ^^^^
  File "C:\Users\mnarv\OneDrive\Desktop\ALL WORK\project_SQL+DB\.venv\Lib\site-packages\mysql\connector\cursor_cext.py", line 356, in execute
    self._connection.cmd_query(
    ~~~~~~~~~~~~~~~~~~~~~~~~~~^
        self._stmt_partition["mappable_stmt"],
        ^^^^^^^^^^^^^^^^^^^^^^^^^^^^^^^^^^^^^^
    ...<2 lines>...
        raw_as_string=self._raw_as_string,
        ^^^^^^^^^^^^^^^^^^^^^^^^^^^^^^^^^^
    )
    ^
  File "C:\Users\mnarv\OneDrive\Desktop\ALL WORK\project_SQL+DB\.venv\Lib\site-packages\mysql\connector\opentelemetry\context_propagation.py", line 97, in wrapper
    return method(cnx, *args, **kwargs)
  File "C:\Users\mnarv\OneDrive\Desktop\ALL WORK\project_SQL+DB\.venv\Lib\site-packages\mysql\connector\connection_cext.py", line 781, in cmd_query
    raise get_mysql_exception(
        err.errno, msg=err.msg, sqlstate=err.sqlstate
    ) from err
mysql.connector.errors.ProgrammingError: 1146 (42S02): Table 'test_db.products' doesn't exist
2025-07-21 17:54:33,983 - ERROR - Error fetching product list: 1146 (42S02): Table 'test_db.products' doesn't exist
Traceback (most recent call last):
  File "C:\Users\mnarv\OneDrive\Desktop\ALL WORK\project_SQL+DB\.venv\Lib\site-packages\mysql\connector\connection_cext.py", line 772, in cmd_query
    self._cmysql.query(
    ~~~~~~~~~~~~~~~~~~^
        query,
        ^^^^^^
    ...<3 lines>...
        query_attrs=self.query_attrs,
        ^^^^^^^^^^^^^^^^^^^^^^^^^^^^^
    )
    ^
_mysql_connector.MySQLInterfaceError: Table 'test_db.products' doesn't exist

The above exception was the direct cause of the following exception:

Traceback (most recent call last):
  File "c:\Users\mnarv\OneDrive\Desktop\ALL WORK\project_SQL+DB\model\inventory_model.py", line 17, in fetch_all_inventory
    cursor.execute("""
    ~~~~~~~~~~~~~~^^^^
        SELECT
        ^^^^^^
    ...<3 lines>...
        FROM products;
        ^^^^^^^^^^^^^^
    """)
    ^^^^
  File "C:\Users\mnarv\OneDrive\Desktop\ALL WORK\project_SQL+DB\.venv\Lib\site-packages\mysql\connector\cursor_cext.py", line 356, in execute
    self._connection.cmd_query(
    ~~~~~~~~~~~~~~~~~~~~~~~~~~^
        self._stmt_partition["mappable_stmt"],
        ^^^^^^^^^^^^^^^^^^^^^^^^^^^^^^^^^^^^^^
    ...<2 lines>...
        raw_as_string=self._raw_as_string,
        ^^^^^^^^^^^^^^^^^^^^^^^^^^^^^^^^^^
    )
    ^
  File "C:\Users\mnarv\OneDrive\Desktop\ALL WORK\project_SQL+DB\.venv\Lib\site-packages\mysql\connector\opentelemetry\context_propagation.py", line 97, in wrapper
    return method(cnx, *args, **kwargs)
  File "C:\Users\mnarv\OneDrive\Desktop\ALL WORK\project_SQL+DB\.venv\Lib\site-packages\mysql\connector\connection_cext.py", line 781, in cmd_query
    raise get_mysql_exception(
        err.errno, msg=err.msg, sqlstate=err.sqlstate
    ) from err
mysql.connector.errors.ProgrammingError: 1146 (42S02): Table 'test_db.products' doesn't exist
2025-07-21 17:54:34,926 - ERROR - Error fetching product list: 1146 (42S02): Table 'test_db.products' doesn't exist
Traceback (most recent call last):
  File "C:\Users\mnarv\OneDrive\Desktop\ALL WORK\project_SQL+DB\.venv\Lib\site-packages\mysql\connector\connection_cext.py", line 772, in cmd_query
    self._cmysql.query(
    ~~~~~~~~~~~~~~~~~~^
        query,
        ^^^^^^
    ...<3 lines>...
        query_attrs=self.query_attrs,
        ^^^^^^^^^^^^^^^^^^^^^^^^^^^^^
    )
    ^
_mysql_connector.MySQLInterfaceError: Table 'test_db.products' doesn't exist

The above exception was the direct cause of the following exception:

Traceback (most recent call last):
  File "c:\Users\mnarv\OneDrive\Desktop\ALL WORK\project_SQL+DB\model\inventory_model.py", line 17, in fetch_all_inventory
    cursor.execute("""
    ~~~~~~~~~~~~~~^^^^
        SELECT
        ^^^^^^
    ...<3 lines>...
        FROM products;
        ^^^^^^^^^^^^^^
    """)
    ^^^^
  File "C:\Users\mnarv\OneDrive\Desktop\ALL WORK\project_SQL+DB\.venv\Lib\site-packages\mysql\connector\cursor_cext.py", line 356, in execute
    self._connection.cmd_query(
    ~~~~~~~~~~~~~~~~~~~~~~~~~~^
        self._stmt_partition["mappable_stmt"],
        ^^^^^^^^^^^^^^^^^^^^^^^^^^^^^^^^^^^^^^
    ...<2 lines>...
        raw_as_string=self._raw_as_string,
        ^^^^^^^^^^^^^^^^^^^^^^^^^^^^^^^^^^
    )
    ^
  File "C:\Users\mnarv\OneDrive\Desktop\ALL WORK\project_SQL+DB\.venv\Lib\site-packages\mysql\connector\opentelemetry\context_propagation.py", line 97, in wrapper
    return method(cnx, *args, **kwargs)
  File "C:\Users\mnarv\OneDrive\Desktop\ALL WORK\project_SQL+DB\.venv\Lib\site-packages\mysql\connector\connection_cext.py", line 781, in cmd_query
    raise get_mysql_exception(
        err.errno, msg=err.msg, sqlstate=err.sqlstate
    ) from err
mysql.connector.errors.ProgrammingError: 1146 (42S02): Table 'test_db.products' doesn't exist
2025-07-21 17:58:32,075 - INFO - User found for email: aayanali1208@gmail.com
2025-07-21 17:58:32,079 - INFO - Inventory ID exists: 3
2025-07-21 18:00:36,344 - INFO - User found for email: aayanali1208@gmail.com
2025-07-21 18:00:36,349 - INFO - Inventory ID exists: 3
2025-07-21 18:41:09,936 - INFO - User found for email: aayanali1208@gmail.com
2025-07-21 18:41:17,026 - INFO - User found for email: aayanali1208@gmail.com
2025-07-21 18:41:17,898 - INFO - User ID found for email: aayanali1208@gmail.com
2025-07-21 18:43:44,515 - INFO - User found for email: aayanali1208@gmail.com
2025-07-21 18:43:44,531 - WARNING - Product ID not found: 3
2025-07-21 18:45:51,243 - INFO - User found for email: aayanali1208@gmail.com
2025-07-21 18:45:51,250 - INFO - Product ID exists: 3
2025-07-21 18:46:00,986 - INFO - User found for email: aayanali1208@gmail.com
2025-07-21 18:46:00,992 - INFO - Product ID exists: 3
2025-07-21 18:54:23,616 - INFO - User found for email: aayanali1208@gmail.com
2025-07-21 18:54:23,620 - INFO - Product ID exists: 3
2025-07-21 18:59:45,976 - INFO - User found for email: aayanali1208@gmail.com
2025-07-21 18:59:45,981 - INFO - Product ID exists: 3
2025-07-21 19:00:05,015 - INFO - User found for email: aayanali1208@gmail.com
2025-07-21 19:00:05,022 - INFO - Product ID exists: 3
2025-07-21 19:00:10,967 - INFO - User found for email: aayanali1208@gmail.com
2025-07-21 19:00:10,972 - INFO - Product ID exists: 3
2025-07-21 19:00:12,631 - INFO - User found for email: aayanali1208@gmail.com
2025-07-21 19:00:12,636 - INFO - Product ID exists: 3
2025-07-21 19:00:58,294 - INFO - User found for email: aayanali1208@gmail.com
2025-07-21 19:00:58,296 - INFO - Product ID exists: 3
2025-07-21 19:02:02,279 - INFO - User found for email: aayanali1208@gmail.com
2025-07-21 19:02:02,283 - INFO - Product ID exists: 3
2025-07-21 19:02:02,302 - ERROR - Error adding item to cart: 1265 (01000): Data truncated for column 'product_size' at row 1
2025-07-21 19:03:12,406 - INFO - User found for email: aayanali1208@gmail.com
2025-07-21 19:03:12,410 - INFO - Product ID exists: 3
2025-07-21 19:03:12,414 - ERROR - Error adding item to cart: 1265 (01000): Data truncated for column 'product_size' at row 1
2025-07-21 19:05:10,708 - INFO - User found for email: aayanali1208@gmail.com
2025-07-21 19:05:10,710 - INFO - Product ID exists: 3
2025-07-21 19:05:10,717 - ERROR - Error adding item to cart: 1265 (01000): Data truncated for column 'product_size' at row 1
2025-07-21 19:08:53,457 - INFO - User found for email: aayanali1208@gmail.com
2025-07-21 19:08:53,461 - INFO - Product ID exists: 3
2025-07-21 19:10:39,808 - INFO - User found for email: aayanali1208@gmail.com
2025-07-21 19:10:39,812 - INFO - Product ID exists: 5
2025-07-21 19:10:42,750 - INFO - User found for email: aayanali1208@gmail.com
2025-07-21 19:10:42,753 - INFO - Product ID exists: 5
2025-07-21 19:10:48,154 - INFO - User found for email: aayanali1208@gmail.com
2025-07-21 19:10:48,156 - INFO - Product ID exists: 5
2025-07-21 19:13:25,457 - INFO - User found for email: aayanali1208@gmail.com
2025-07-21 19:14:29,992 - INFO - User found for email: aayanali1208@gmail.com
2025-07-21 19:14:30,458 - INFO - User ID found for email: aayanali1208@gmail.com
2025-07-21 19:15:08,687 - INFO - User found for email: aayanali1208@gmail.com
2025-07-21 19:15:17,098 - INFO - User found for email: aayanali1208@gmail.com
2025-07-21 21:45:18,345 - INFO - User found for email: aayanali1208@gmail.com
2025-07-21 21:46:01,976 - INFO - User found for email: aayanali1208@gmail.com
2025-07-21 21:46:10,036 - INFO - User found for email: aayanali1208@gmail.com
2025-07-21 21:46:10,331 - INFO - User ID found for email: aayanali1208@gmail.com
2025-07-21 21:46:55,689 - INFO - User found for email: aayanali1208@gmail.com
2025-07-21 21:47:30,399 - INFO - User found for email: aayanali1208@gmail.com
2025-07-21 21:49:16,503 - INFO - User found for email: aayanali1208@gmail.com
2025-07-21 21:49:37,112 - INFO - User found for email: aayanali1208@gmail.com
2025-07-21 21:53:24,292 - INFO - User found for email: aayanali1208@gmail.com
2025-07-21 21:55:52,555 - INFO - User found for email: aayanali1208@gmail.com
2025-07-21 21:58:26,650 - INFO - User found for email: aayanali1208@gmail.com
2025-07-21 22:00:55,489 - WARNING - Product ID not found: 9
2025-07-21 22:01:00,086 - INFO - Product ID exists: 3
2025-07-21 22:01:00,093 - WARNING - Invalid cart ID: 9
2025-07-21 22:01:10,132 - INFO - Product ID exists: 3
2025-07-21 22:01:10,139 - WARNING - Invalid cart ID: 9
2025-07-21 22:01:57,598 - INFO - Product ID exists: 3
2025-07-21 22:01:57,600 - ERROR - Error checking cart ID (9): 1064 (42000): You have an error in your SQL syntax; check the manual that corresponds to your MySQL server version for the right syntax to use near 'as id = 9' at line 1
Traceback (most recent call last):
  File "C:\Users\mnarv\OneDrive\Desktop\ALL WORK\project_SQL+DB\.venv\Lib\site-packages\mysql\connector\connection_cext.py", line 772, in cmd_query
    self._cmysql.query(
    ~~~~~~~~~~~~~~~~~~^
        query,
        ^^^^^^
    ...<3 lines>...
        query_attrs=self.query_attrs,
        ^^^^^^^^^^^^^^^^^^^^^^^^^^^^^
    )
    ^
_mysql_connector.MySQLInterfaceError: You have an error in your SQL syntax; check the manual that corresponds to your MySQL server version for the right syntax to use near 'as id = 9' at line 1

The above exception was the direct cause of the following exception:

Traceback (most recent call last):
  File "c:\Users\mnarv\OneDrive\Desktop\ALL WORK\project_SQL+DB\model\cart_model.py", line 122, in is_valid_cart_id
    cursor.execute("SELECT * FROM cart_items WHERE cart_id as id = %s", (cart_id,))
    ~~~~~~~~~~~~~~^^^^^^^^^^^^^^^^^^^^^^^^^^^^^^^^^^^^^^^^^^^^^^^^^^^^^^^^^^^^^^^^^
  File "C:\Users\mnarv\OneDrive\Desktop\ALL WORK\project_SQL+DB\.venv\Lib\site-packages\mysql\connector\cursor_cext.py", line 356, in execute
    self._connection.cmd_query(
    ~~~~~~~~~~~~~~~~~~~~~~~~~~^
        self._stmt_partition["mappable_stmt"],
        ^^^^^^^^^^^^^^^^^^^^^^^^^^^^^^^^^^^^^^
    ...<2 lines>...
        raw_as_string=self._raw_as_string,
        ^^^^^^^^^^^^^^^^^^^^^^^^^^^^^^^^^^
    )
    ^
  File "C:\Users\mnarv\OneDrive\Desktop\ALL WORK\project_SQL+DB\.venv\Lib\site-packages\mysql\connector\opentelemetry\context_propagation.py", line 97, in wrapper
    return method(cnx, *args, **kwargs)
  File "C:\Users\mnarv\OneDrive\Desktop\ALL WORK\project_SQL+DB\.venv\Lib\site-packages\mysql\connector\connection_cext.py", line 781, in cmd_query
    raise get_mysql_exception(
        err.errno, msg=err.msg, sqlstate=err.sqlstate
    ) from err
mysql.connector.errors.ProgrammingError: 1064 (42000): You have an error in your SQL syntax; check the manual that corresponds to your MySQL server version for the right syntax to use near 'as id = 9' at line 1
2025-07-21 22:02:13,748 - INFO - Product ID exists: 3
2025-07-21 22:02:21,358 - INFO - Product ID exists: 3
2025-07-21 22:02:31,411 - INFO - Product ID exists: 3
2025-07-21 22:02:34,209 - INFO - Product ID exists: 3
2025-07-21 22:02:44,911 - INFO - Product ID exists: 3
2025-07-21 22:04:40,453 - WARNING - Invalid cart ID: 6
2025-07-21 22:04:44,611 - WARNING - Invalid cart ID: 7
2025-07-21 22:04:48,446 - WARNING - Invalid cart ID: 7
2025-07-21 22:07:32,143 - INFO - User found for email: aayanali1208@gmail.com
2025-07-21 22:07:33,008 - ERROR - Error inserting order for 84029: 1452 (23000): Cannot add or update a child row: a foreign key constraint fails (`test_db`.`orders`, CONSTRAINT `fk_orders_cart` FOREIGN KEY (`product_id`) REFERENCES `inventory` (`id`))
Traceback (most recent call last):
  File "C:\Users\mnarv\OneDrive\Desktop\ALL WORK\project_SQL+DB\.venv\Lib\site-packages\mysql\connector\connection_cext.py", line 772, in cmd_query
    self._cmysql.query(
    ~~~~~~~~~~~~~~~~~~^
        query,
        ^^^^^^
    ...<3 lines>...
        query_attrs=self.query_attrs,
        ^^^^^^^^^^^^^^^^^^^^^^^^^^^^^
    )
    ^
_mysql_connector.MySQLInterfaceError: Cannot add or update a child row: a foreign key constraint fails (`test_db`.`orders`, CONSTRAINT `fk_orders_cart` FOREIGN KEY (`product_id`) REFERENCES `inventory` (`id`))

The above exception was the direct cause of the following exception:

Traceback (most recent call last):
  File "c:\Users\mnarv\OneDrive\Desktop\ALL WORK\project_SQL+DB\model\order_model.py", line 27, in insert_order
    cursor.execute(
    ~~~~~~~~~~~~~~^
        "INSERT INTO orders (user_id, product_id, address, city, country, zipcode, phone_number) VALUES (%s, %s, %s, %s, %s, %s, %s)",
        ^^^^^^^^^^^^^^^^^^^^^^^^^^^^^^^^^^^^^^^^^^^^^^^^^^^^^^^^^^^^^^^^^^^^^^^^^^^^^^^^^^^^^^^^^^^^^^^^^^^^^^^^^^^^^^^^^^^^^^^^^^^^^^
        (user_id, product_id, address, city, country, zipcode, phone_number)
        ^^^^^^^^^^^^^^^^^^^^^^^^^^^^^^^^^^^^^^^^^^^^^^^^^^^^^^^^^^^^^^^^^^^^
    )
    ^
  File "C:\Users\mnarv\OneDrive\Desktop\ALL WORK\project_SQL+DB\.venv\Lib\site-packages\mysql\connector\cursor_cext.py", line 356, in execute
    self._connection.cmd_query(
    ~~~~~~~~~~~~~~~~~~~~~~~~~~^
        self._stmt_partition["mappable_stmt"],
        ^^^^^^^^^^^^^^^^^^^^^^^^^^^^^^^^^^^^^^
    ...<2 lines>...
        raw_as_string=self._raw_as_string,
        ^^^^^^^^^^^^^^^^^^^^^^^^^^^^^^^^^^
    )
    ^
  File "C:\Users\mnarv\OneDrive\Desktop\ALL WORK\project_SQL+DB\.venv\Lib\site-packages\mysql\connector\opentelemetry\context_propagation.py", line 97, in wrapper
    return method(cnx, *args, **kwargs)
  File "C:\Users\mnarv\OneDrive\Desktop\ALL WORK\project_SQL+DB\.venv\Lib\site-packages\mysql\connector\connection_cext.py", line 781, in cmd_query
    raise get_mysql_exception(
        err.errno, msg=err.msg, sqlstate=err.sqlstate
    ) from err
mysql.connector.errors.IntegrityError: 1452 (23000): Cannot add or update a child row: a foreign key constraint fails (`test_db`.`orders`, CONSTRAINT `fk_orders_cart` FOREIGN KEY (`product_id`) REFERENCES `inventory` (`id`))
2025-07-21 22:07:33,051 - WARNING - Order not found for user 84029 and inventory 5
2025-07-21 22:19:51,206 - INFO - User found for email: aayanali1208@gmail.com
2025-07-21 22:20:14,221 - INFO - User found for email: aayanali1208@gmail.com
2025-07-21 22:20:20,082 - INFO - User found for email: aayanali1208@gmail.com
2025-07-21 22:20:20,849 - INFO - User ID found for email: aayanali1208@gmail.com
2025-07-21 22:20:42,943 - INFO - User found for email: aayanali1208@gmail.com
2025-07-21 22:20:43,668 - ERROR - Error inserting order for 84029: 1452 (23000): Cannot add or update a child row: a foreign key constraint fails (`test_db`.`orders`, CONSTRAINT `fk_orders_cart` FOREIGN KEY (`product_id`) REFERENCES `inventory` (`id`))
Traceback (most recent call last):
  File "C:\Users\mnarv\OneDrive\Desktop\ALL WORK\project_SQL+DB\.venv\Lib\site-packages\mysql\connector\connection_cext.py", line 772, in cmd_query
    self._cmysql.query(
    ~~~~~~~~~~~~~~~~~~^
        query,
        ^^^^^^
    ...<3 lines>...
        query_attrs=self.query_attrs,
        ^^^^^^^^^^^^^^^^^^^^^^^^^^^^^
    )
    ^
_mysql_connector.MySQLInterfaceError: Cannot add or update a child row: a foreign key constraint fails (`test_db`.`orders`, CONSTRAINT `fk_orders_cart` FOREIGN KEY (`product_id`) REFERENCES `inventory` (`id`))

The above exception was the direct cause of the following exception:

Traceback (most recent call last):
  File "c:\Users\mnarv\OneDrive\Desktop\ALL WORK\project_SQL+DB\model\order_model.py", line 27, in insert_order
    cursor.execute(
    ~~~~~~~~~~~~~~^
        "INSERT INTO orders (user_id, product_id, address, city, country, zipcode, phone_number) VALUES (%s, %s, %s, %s, %s, %s, %s)",
        ^^^^^^^^^^^^^^^^^^^^^^^^^^^^^^^^^^^^^^^^^^^^^^^^^^^^^^^^^^^^^^^^^^^^^^^^^^^^^^^^^^^^^^^^^^^^^^^^^^^^^^^^^^^^^^^^^^^^^^^^^^^^^^
        (user_id, product_id, address, city, country, zipcode, phone_number)
        ^^^^^^^^^^^^^^^^^^^^^^^^^^^^^^^^^^^^^^^^^^^^^^^^^^^^^^^^^^^^^^^^^^^^
    )
    ^
  File "C:\Users\mnarv\OneDrive\Desktop\ALL WORK\project_SQL+DB\.venv\Lib\site-packages\mysql\connector\cursor_cext.py", line 356, in execute
    self._connection.cmd_query(
    ~~~~~~~~~~~~~~~~~~~~~~~~~~^
        self._stmt_partition["mappable_stmt"],
        ^^^^^^^^^^^^^^^^^^^^^^^^^^^^^^^^^^^^^^
    ...<2 lines>...
        raw_as_string=self._raw_as_string,
        ^^^^^^^^^^^^^^^^^^^^^^^^^^^^^^^^^^
    )
    ^
  File "C:\Users\mnarv\OneDrive\Desktop\ALL WORK\project_SQL+DB\.venv\Lib\site-packages\mysql\connector\opentelemetry\context_propagation.py", line 97, in wrapper
    return method(cnx, *args, **kwargs)
  File "C:\Users\mnarv\OneDrive\Desktop\ALL WORK\project_SQL+DB\.venv\Lib\site-packages\mysql\connector\connection_cext.py", line 781, in cmd_query
    raise get_mysql_exception(
        err.errno, msg=err.msg, sqlstate=err.sqlstate
    ) from err
mysql.connector.errors.IntegrityError: 1452 (23000): Cannot add or update a child row: a foreign key constraint fails (`test_db`.`orders`, CONSTRAINT `fk_orders_cart` FOREIGN KEY (`product_id`) REFERENCES `inventory` (`id`))
2025-07-21 22:20:43,693 - WARNING - Order not found for user 84029 and inventory 5
2025-07-21 22:22:19,207 - INFO - User found for email: aayanali1208@gmail.com
2025-07-21 22:22:19,664 - ERROR - Error inserting order for 84029: 1452 (23000): Cannot add or update a child row: a foreign key constraint fails (`test_db`.`orders`, CONSTRAINT `fk_orders_cart` FOREIGN KEY (`product_id`) REFERENCES `inventory` (`id`))
Traceback (most recent call last):
  File "C:\Users\mnarv\OneDrive\Desktop\ALL WORK\project_SQL+DB\.venv\Lib\site-packages\mysql\connector\connection_cext.py", line 772, in cmd_query
    self._cmysql.query(
    ~~~~~~~~~~~~~~~~~~^
        query,
        ^^^^^^
    ...<3 lines>...
        query_attrs=self.query_attrs,
        ^^^^^^^^^^^^^^^^^^^^^^^^^^^^^
    )
    ^
_mysql_connector.MySQLInterfaceError: Cannot add or update a child row: a foreign key constraint fails (`test_db`.`orders`, CONSTRAINT `fk_orders_cart` FOREIGN KEY (`product_id`) REFERENCES `inventory` (`id`))

The above exception was the direct cause of the following exception:

Traceback (most recent call last):
  File "c:\Users\mnarv\OneDrive\Desktop\ALL WORK\project_SQL+DB\model\order_model.py", line 27, in insert_order
    cursor.execute(
    ~~~~~~~~~~~~~~^
        "INSERT INTO orders (user_id, product_id, address, city, country, zipcode, phone_number) VALUES (%s, %s, %s, %s, %s, %s, %s)",
        ^^^^^^^^^^^^^^^^^^^^^^^^^^^^^^^^^^^^^^^^^^^^^^^^^^^^^^^^^^^^^^^^^^^^^^^^^^^^^^^^^^^^^^^^^^^^^^^^^^^^^^^^^^^^^^^^^^^^^^^^^^^^^^
        (user_id, product_id, address, city, country, zipcode, phone_number)
        ^^^^^^^^^^^^^^^^^^^^^^^^^^^^^^^^^^^^^^^^^^^^^^^^^^^^^^^^^^^^^^^^^^^^
    )
    ^
  File "C:\Users\mnarv\OneDrive\Desktop\ALL WORK\project_SQL+DB\.venv\Lib\site-packages\mysql\connector\cursor_cext.py", line 356, in execute
    self._connection.cmd_query(
    ~~~~~~~~~~~~~~~~~~~~~~~~~~^
        self._stmt_partition["mappable_stmt"],
        ^^^^^^^^^^^^^^^^^^^^^^^^^^^^^^^^^^^^^^
    ...<2 lines>...
        raw_as_string=self._raw_as_string,
        ^^^^^^^^^^^^^^^^^^^^^^^^^^^^^^^^^^
    )
    ^
  File "C:\Users\mnarv\OneDrive\Desktop\ALL WORK\project_SQL+DB\.venv\Lib\site-packages\mysql\connector\opentelemetry\context_propagation.py", line 97, in wrapper
    return method(cnx, *args, **kwargs)
  File "C:\Users\mnarv\OneDrive\Desktop\ALL WORK\project_SQL+DB\.venv\Lib\site-packages\mysql\connector\connection_cext.py", line 781, in cmd_query
    raise get_mysql_exception(
        err.errno, msg=err.msg, sqlstate=err.sqlstate
    ) from err
mysql.connector.errors.IntegrityError: 1452 (23000): Cannot add or update a child row: a foreign key constraint fails (`test_db`.`orders`, CONSTRAINT `fk_orders_cart` FOREIGN KEY (`product_id`) REFERENCES `inventory` (`id`))
2025-07-21 22:22:19,682 - WARNING - Order not found for user 84029 and inventory 5
2025-07-21 22:24:26,826 - INFO - User found for email: aayanali1208@gmail.com
2025-07-21 22:24:27,156 - ERROR - Error inserting order for 84029: 1452 (23000): Cannot add or update a child row: a foreign key constraint fails (`test_db`.`orders`, CONSTRAINT `fk_orders_cart` FOREIGN KEY (`product_id`) REFERENCES `inventory` (`id`))
Traceback (most recent call last):
  File "C:\Users\mnarv\OneDrive\Desktop\ALL WORK\project_SQL+DB\.venv\Lib\site-packages\mysql\connector\connection_cext.py", line 772, in cmd_query
    self._cmysql.query(
    ~~~~~~~~~~~~~~~~~~^
        query,
        ^^^^^^
    ...<3 lines>...
        query_attrs=self.query_attrs,
        ^^^^^^^^^^^^^^^^^^^^^^^^^^^^^
    )
    ^
_mysql_connector.MySQLInterfaceError: Cannot add or update a child row: a foreign key constraint fails (`test_db`.`orders`, CONSTRAINT `fk_orders_cart` FOREIGN KEY (`product_id`) REFERENCES `inventory` (`id`))

The above exception was the direct cause of the following exception:

Traceback (most recent call last):
  File "c:\Users\mnarv\OneDrive\Desktop\ALL WORK\project_SQL+DB\model\order_model.py", line 27, in insert_order
    cursor.execute(
    ~~~~~~~~~~~~~~^
        "INSERT INTO orders (user_id, product_id, address, city, country, zipcode, phone_number) VALUES (%s, %s, %s, %s, %s, %s, %s)",
        ^^^^^^^^^^^^^^^^^^^^^^^^^^^^^^^^^^^^^^^^^^^^^^^^^^^^^^^^^^^^^^^^^^^^^^^^^^^^^^^^^^^^^^^^^^^^^^^^^^^^^^^^^^^^^^^^^^^^^^^^^^^^^^
        (user_id, product_id, address, city, country, zipcode, phone_number)
        ^^^^^^^^^^^^^^^^^^^^^^^^^^^^^^^^^^^^^^^^^^^^^^^^^^^^^^^^^^^^^^^^^^^^
    )
    ^
  File "C:\Users\mnarv\OneDrive\Desktop\ALL WORK\project_SQL+DB\.venv\Lib\site-packages\mysql\connector\cursor_cext.py", line 356, in execute
    self._connection.cmd_query(
    ~~~~~~~~~~~~~~~~~~~~~~~~~~^
        self._stmt_partition["mappable_stmt"],
        ^^^^^^^^^^^^^^^^^^^^^^^^^^^^^^^^^^^^^^
    ...<2 lines>...
        raw_as_string=self._raw_as_string,
        ^^^^^^^^^^^^^^^^^^^^^^^^^^^^^^^^^^
    )
    ^
  File "C:\Users\mnarv\OneDrive\Desktop\ALL WORK\project_SQL+DB\.venv\Lib\site-packages\mysql\connector\opentelemetry\context_propagation.py", line 97, in wrapper
    return method(cnx, *args, **kwargs)
  File "C:\Users\mnarv\OneDrive\Desktop\ALL WORK\project_SQL+DB\.venv\Lib\site-packages\mysql\connector\connection_cext.py", line 781, in cmd_query
    raise get_mysql_exception(
        err.errno, msg=err.msg, sqlstate=err.sqlstate
    ) from err
mysql.connector.errors.IntegrityError: 1452 (23000): Cannot add or update a child row: a foreign key constraint fails (`test_db`.`orders`, CONSTRAINT `fk_orders_cart` FOREIGN KEY (`product_id`) REFERENCES `inventory` (`id`))
2025-07-21 22:24:27,166 - WARNING - Order not found for user 84029 and inventory 5
2025-07-21 22:26:17,645 - INFO - User found for email: aayanali1208@gmail.com
2025-07-21 22:26:18,187 - ERROR - Error inserting order for 84029: 1452 (23000): Cannot add or update a child row: a foreign key constraint fails (`test_db`.`orders`, CONSTRAINT `fk_orders_cart` FOREIGN KEY (`product_id`) REFERENCES `inventory` (`id`))
Traceback (most recent call last):
  File "C:\Users\mnarv\OneDrive\Desktop\ALL WORK\project_SQL+DB\.venv\Lib\site-packages\mysql\connector\connection_cext.py", line 772, in cmd_query
    self._cmysql.query(
    ~~~~~~~~~~~~~~~~~~^
        query,
        ^^^^^^
    ...<3 lines>...
        query_attrs=self.query_attrs,
        ^^^^^^^^^^^^^^^^^^^^^^^^^^^^^
    )
    ^
_mysql_connector.MySQLInterfaceError: Cannot add or update a child row: a foreign key constraint fails (`test_db`.`orders`, CONSTRAINT `fk_orders_cart` FOREIGN KEY (`product_id`) REFERENCES `inventory` (`id`))

The above exception was the direct cause of the following exception:

Traceback (most recent call last):
  File "c:\Users\mnarv\OneDrive\Desktop\ALL WORK\project_SQL+DB\model\order_model.py", line 27, in insert_order
    cursor.execute(
    ~~~~~~~~~~~~~~^
        "INSERT INTO orders (user_id, product_id, address, city, country, zipcode, phone_number) VALUES (%s, %s, %s, %s, %s, %s, %s)",
        ^^^^^^^^^^^^^^^^^^^^^^^^^^^^^^^^^^^^^^^^^^^^^^^^^^^^^^^^^^^^^^^^^^^^^^^^^^^^^^^^^^^^^^^^^^^^^^^^^^^^^^^^^^^^^^^^^^^^^^^^^^^^^^
        (user_id, product_id, address, city, country, zipcode, phone_number)
        ^^^^^^^^^^^^^^^^^^^^^^^^^^^^^^^^^^^^^^^^^^^^^^^^^^^^^^^^^^^^^^^^^^^^
    )
    ^
  File "C:\Users\mnarv\OneDrive\Desktop\ALL WORK\project_SQL+DB\.venv\Lib\site-packages\mysql\connector\cursor_cext.py", line 356, in execute
    self._connection.cmd_query(
    ~~~~~~~~~~~~~~~~~~~~~~~~~~^
        self._stmt_partition["mappable_stmt"],
        ^^^^^^^^^^^^^^^^^^^^^^^^^^^^^^^^^^^^^^
    ...<2 lines>...
        raw_as_string=self._raw_as_string,
        ^^^^^^^^^^^^^^^^^^^^^^^^^^^^^^^^^^
    )
    ^
  File "C:\Users\mnarv\OneDrive\Desktop\ALL WORK\project_SQL+DB\.venv\Lib\site-packages\mysql\connector\opentelemetry\context_propagation.py", line 97, in wrapper
    return method(cnx, *args, **kwargs)
  File "C:\Users\mnarv\OneDrive\Desktop\ALL WORK\project_SQL+DB\.venv\Lib\site-packages\mysql\connector\connection_cext.py", line 781, in cmd_query
    raise get_mysql_exception(
        err.errno, msg=err.msg, sqlstate=err.sqlstate
    ) from err
mysql.connector.errors.IntegrityError: 1452 (23000): Cannot add or update a child row: a foreign key constraint fails (`test_db`.`orders`, CONSTRAINT `fk_orders_cart` FOREIGN KEY (`product_id`) REFERENCES `inventory` (`id`))
2025-07-21 22:26:18,202 - WARNING - Order not found for user 84029 and inventory 5
2025-07-21 22:34:08,137 - INFO - User found for email: aayanali1208@gmail.com
2025-07-21 22:34:08,490 - ERROR - Error inserting order for 84029: 1452 (23000): Cannot add or update a child row: a foreign key constraint fails (`test_db`.`orders`, CONSTRAINT `fk_orders_cart` FOREIGN KEY (`product_id`) REFERENCES `inventory` (`id`))
Traceback (most recent call last):
  File "C:\Users\mnarv\OneDrive\Desktop\ALL WORK\project_SQL+DB\.venv\Lib\site-packages\mysql\connector\connection_cext.py", line 772, in cmd_query
    self._cmysql.query(
    ~~~~~~~~~~~~~~~~~~^
        query,
        ^^^^^^
    ...<3 lines>...
        query_attrs=self.query_attrs,
        ^^^^^^^^^^^^^^^^^^^^^^^^^^^^^
    )
    ^
_mysql_connector.MySQLInterfaceError: Cannot add or update a child row: a foreign key constraint fails (`test_db`.`orders`, CONSTRAINT `fk_orders_cart` FOREIGN KEY (`product_id`) REFERENCES `inventory` (`id`))

The above exception was the direct cause of the following exception:

Traceback (most recent call last):
  File "c:\Users\mnarv\OneDrive\Desktop\ALL WORK\project_SQL+DB\model\order_model.py", line 27, in insert_order
    cursor.execute(
    ~~~~~~~~~~~~~~^
        "INSERT INTO orders (user_id, product_id, address, city, country, zipcode, phone_number) VALUES (%s, %s, %s, %s, %s, %s, %s)",
        ^^^^^^^^^^^^^^^^^^^^^^^^^^^^^^^^^^^^^^^^^^^^^^^^^^^^^^^^^^^^^^^^^^^^^^^^^^^^^^^^^^^^^^^^^^^^^^^^^^^^^^^^^^^^^^^^^^^^^^^^^^^^^^
        (user_id, product_id, address, city, country, zipcode, phone_number)
        ^^^^^^^^^^^^^^^^^^^^^^^^^^^^^^^^^^^^^^^^^^^^^^^^^^^^^^^^^^^^^^^^^^^^
    )
    ^
  File "C:\Users\mnarv\OneDrive\Desktop\ALL WORK\project_SQL+DB\.venv\Lib\site-packages\mysql\connector\cursor_cext.py", line 356, in execute
    self._connection.cmd_query(
    ~~~~~~~~~~~~~~~~~~~~~~~~~~^
        self._stmt_partition["mappable_stmt"],
        ^^^^^^^^^^^^^^^^^^^^^^^^^^^^^^^^^^^^^^
    ...<2 lines>...
        raw_as_string=self._raw_as_string,
        ^^^^^^^^^^^^^^^^^^^^^^^^^^^^^^^^^^
    )
    ^
  File "C:\Users\mnarv\OneDrive\Desktop\ALL WORK\project_SQL+DB\.venv\Lib\site-packages\mysql\connector\opentelemetry\context_propagation.py", line 97, in wrapper
    return method(cnx, *args, **kwargs)
  File "C:\Users\mnarv\OneDrive\Desktop\ALL WORK\project_SQL+DB\.venv\Lib\site-packages\mysql\connector\connection_cext.py", line 781, in cmd_query
    raise get_mysql_exception(
        err.errno, msg=err.msg, sqlstate=err.sqlstate
    ) from err
mysql.connector.errors.IntegrityError: 1452 (23000): Cannot add or update a child row: a foreign key constraint fails (`test_db`.`orders`, CONSTRAINT `fk_orders_cart` FOREIGN KEY (`product_id`) REFERENCES `inventory` (`id`))
2025-07-21 22:34:08,501 - WARNING - Order not found for user 84029 and inventory 5
2025-07-21 22:34:08,521 - ERROR - Error inserting order items for order None: 1452 (23000): Cannot add or update a child row: a foreign key constraint fails (`test_db`.`order_items`, CONSTRAINT `fk_orders_order` FOREIGN KEY (`product_id`) REFERENCES `inventory` (`id`))
Traceback (most recent call last):
  File "C:\Users\mnarv\OneDrive\Desktop\ALL WORK\project_SQL+DB\.venv\Lib\site-packages\mysql\connector\connection_cext.py", line 772, in cmd_query
    self._cmysql.query(
    ~~~~~~~~~~~~~~~~~~^
        query,
        ^^^^^^
    ...<3 lines>...
        query_attrs=self.query_attrs,
        ^^^^^^^^^^^^^^^^^^^^^^^^^^^^^
    )
    ^
_mysql_connector.MySQLInterfaceError: Cannot add or update a child row: a foreign key constraint fails (`test_db`.`order_items`, CONSTRAINT `fk_orders_order` FOREIGN KEY (`product_id`) REFERENCES `inventory` (`id`))

The above exception was the direct cause of the following exception:

Traceback (most recent call last):
  File "c:\Users\mnarv\OneDrive\Desktop\ALL WORK\project_SQL+DB\model\order_model.py", line 73, in order_items
    cursor.execute(
    ~~~~~~~~~~~~~~^
        "INSERT INTO order_items (order_id, product_id, quantity, product_size, product_color, product_quality, product_price, product_name) VALUES (%s, %s, %s, %s, %s, %s, %s, %s)",
        ^^^^^^^^^^^^^^^^^^^^^^^^^^^^^^^^^^^^^^^^^^^^^^^^^^^^^^^^^^^^^^^^^^^^^^^^^^^^^^^^^^^^^^^^^^^^^^^^^^^^^^^^^^^^^^^^^^^^^^^^^^^^^^^^^^^^^^^^^^^^^^^^^^^^^^^^^^^^^^^^^^^^^^^^^^^^^^
        (order_id, product_id, quantity, size, color, quality, product_price, product_name)
        ^^^^^^^^^^^^^^^^^^^^^^^^^^^^^^^^^^^^^^^^^^^^^^^^^^^^^^^^^^^^^^^^^^^^^^^^^^^^^^^^^^^
    )
    ^
  File "C:\Users\mnarv\OneDrive\Desktop\ALL WORK\project_SQL+DB\.venv\Lib\site-packages\mysql\connector\cursor_cext.py", line 356, in execute
    self._connection.cmd_query(
    ~~~~~~~~~~~~~~~~~~~~~~~~~~^
        self._stmt_partition["mappable_stmt"],
        ^^^^^^^^^^^^^^^^^^^^^^^^^^^^^^^^^^^^^^
    ...<2 lines>...
        raw_as_string=self._raw_as_string,
        ^^^^^^^^^^^^^^^^^^^^^^^^^^^^^^^^^^
    )
    ^
  File "C:\Users\mnarv\OneDrive\Desktop\ALL WORK\project_SQL+DB\.venv\Lib\site-packages\mysql\connector\opentelemetry\context_propagation.py", line 97, in wrapper
    return method(cnx, *args, **kwargs)
  File "C:\Users\mnarv\OneDrive\Desktop\ALL WORK\project_SQL+DB\.venv\Lib\site-packages\mysql\connector\connection_cext.py", line 781, in cmd_query
    raise get_mysql_exception(
        err.errno, msg=err.msg, sqlstate=err.sqlstate
    ) from err
mysql.connector.errors.IntegrityError: 1452 (23000): Cannot add or update a child row: a foreign key constraint fails (`test_db`.`order_items`, CONSTRAINT `fk_orders_order` FOREIGN KEY (`product_id`) REFERENCES `inventory` (`id`))
2025-07-21 22:39:50,009 - INFO - User found for email: aayanali1208@gmail.com
2025-07-21 22:41:09,369 - INFO - User found for email: aayanali1208@gmail.com
2025-07-21 22:41:09,892 - ERROR - Error inserting order for 84029: 1452 (23000): Cannot add or update a child row: a foreign key constraint fails (`test_db`.`orders`, CONSTRAINT `fk_orders_cart` FOREIGN KEY (`product_id`) REFERENCES `inventory` (`id`))
Traceback (most recent call last):
  File "C:\Users\mnarv\OneDrive\Desktop\ALL WORK\project_SQL+DB\.venv\Lib\site-packages\mysql\connector\connection_cext.py", line 772, in cmd_query
    self._cmysql.query(
    ~~~~~~~~~~~~~~~~~~^
        query,
        ^^^^^^
    ...<3 lines>...
        query_attrs=self.query_attrs,
        ^^^^^^^^^^^^^^^^^^^^^^^^^^^^^
    )
    ^
_mysql_connector.MySQLInterfaceError: Cannot add or update a child row: a foreign key constraint fails (`test_db`.`orders`, CONSTRAINT `fk_orders_cart` FOREIGN KEY (`product_id`) REFERENCES `inventory` (`id`))

The above exception was the direct cause of the following exception:

Traceback (most recent call last):
  File "c:\Users\mnarv\OneDrive\Desktop\ALL WORK\project_SQL+DB\model\order_model.py", line 27, in insert_order
    cursor.execute(
    ~~~~~~~~~~~~~~^
        "INSERT INTO orders (user_id, product_id, address, city, country, zipcode, phone_number) VALUES (%s, %s, %s, %s, %s, %s, %s)",
        ^^^^^^^^^^^^^^^^^^^^^^^^^^^^^^^^^^^^^^^^^^^^^^^^^^^^^^^^^^^^^^^^^^^^^^^^^^^^^^^^^^^^^^^^^^^^^^^^^^^^^^^^^^^^^^^^^^^^^^^^^^^^^^
        (user_id, product_id, address, city, country, zipcode, phone_number)
        ^^^^^^^^^^^^^^^^^^^^^^^^^^^^^^^^^^^^^^^^^^^^^^^^^^^^^^^^^^^^^^^^^^^^
    )
    ^
  File "C:\Users\mnarv\OneDrive\Desktop\ALL WORK\project_SQL+DB\.venv\Lib\site-packages\mysql\connector\cursor_cext.py", line 356, in execute
    self._connection.cmd_query(
    ~~~~~~~~~~~~~~~~~~~~~~~~~~^
        self._stmt_partition["mappable_stmt"],
        ^^^^^^^^^^^^^^^^^^^^^^^^^^^^^^^^^^^^^^
    ...<2 lines>...
        raw_as_string=self._raw_as_string,
        ^^^^^^^^^^^^^^^^^^^^^^^^^^^^^^^^^^
    )
    ^
  File "C:\Users\mnarv\OneDrive\Desktop\ALL WORK\project_SQL+DB\.venv\Lib\site-packages\mysql\connector\opentelemetry\context_propagation.py", line 97, in wrapper
    return method(cnx, *args, **kwargs)
  File "C:\Users\mnarv\OneDrive\Desktop\ALL WORK\project_SQL+DB\.venv\Lib\site-packages\mysql\connector\connection_cext.py", line 781, in cmd_query
    raise get_mysql_exception(
        err.errno, msg=err.msg, sqlstate=err.sqlstate
    ) from err
mysql.connector.errors.IntegrityError: 1452 (23000): Cannot add or update a child row: a foreign key constraint fails (`test_db`.`orders`, CONSTRAINT `fk_orders_cart` FOREIGN KEY (`product_id`) REFERENCES `inventory` (`id`))
2025-07-21 22:43:39,958 - INFO - User found for email: aayanali1208@gmail.com
2025-07-21 22:43:40,308 - ERROR - Error inserting order for 84029: 1452 (23000): Cannot add or update a child row: a foreign key constraint fails (`test_db`.`orders`, CONSTRAINT `fk_orders_cart` FOREIGN KEY (`product_id`) REFERENCES `inventory` (`id`))
Traceback (most recent call last):
  File "C:\Users\mnarv\OneDrive\Desktop\ALL WORK\project_SQL+DB\.venv\Lib\site-packages\mysql\connector\connection_cext.py", line 772, in cmd_query
    self._cmysql.query(
    ~~~~~~~~~~~~~~~~~~^
        query,
        ^^^^^^
    ...<3 lines>...
        query_attrs=self.query_attrs,
        ^^^^^^^^^^^^^^^^^^^^^^^^^^^^^
    )
    ^
_mysql_connector.MySQLInterfaceError: Cannot add or update a child row: a foreign key constraint fails (`test_db`.`orders`, CONSTRAINT `fk_orders_cart` FOREIGN KEY (`product_id`) REFERENCES `inventory` (`id`))

The above exception was the direct cause of the following exception:

Traceback (most recent call last):
  File "c:\Users\mnarv\OneDrive\Desktop\ALL WORK\project_SQL+DB\model\order_model.py", line 27, in insert_order
    cursor.execute(
    ~~~~~~~~~~~~~~^
        "INSERT INTO orders (user_id, product_id, address, city, country, zipcode, phone_number) VALUES (%s, %s, %s, %s, %s, %s, %s)",
        ^^^^^^^^^^^^^^^^^^^^^^^^^^^^^^^^^^^^^^^^^^^^^^^^^^^^^^^^^^^^^^^^^^^^^^^^^^^^^^^^^^^^^^^^^^^^^^^^^^^^^^^^^^^^^^^^^^^^^^^^^^^^^^
        (user_id, product_id, address, city, country, zipcode, phone_number)
        ^^^^^^^^^^^^^^^^^^^^^^^^^^^^^^^^^^^^^^^^^^^^^^^^^^^^^^^^^^^^^^^^^^^^
    )
    ^
  File "C:\Users\mnarv\OneDrive\Desktop\ALL WORK\project_SQL+DB\.venv\Lib\site-packages\mysql\connector\cursor_cext.py", line 356, in execute
    self._connection.cmd_query(
    ~~~~~~~~~~~~~~~~~~~~~~~~~~^
        self._stmt_partition["mappable_stmt"],
        ^^^^^^^^^^^^^^^^^^^^^^^^^^^^^^^^^^^^^^
    ...<2 lines>...
        raw_as_string=self._raw_as_string,
        ^^^^^^^^^^^^^^^^^^^^^^^^^^^^^^^^^^
    )
    ^
  File "C:\Users\mnarv\OneDrive\Desktop\ALL WORK\project_SQL+DB\.venv\Lib\site-packages\mysql\connector\opentelemetry\context_propagation.py", line 97, in wrapper
    return method(cnx, *args, **kwargs)
  File "C:\Users\mnarv\OneDrive\Desktop\ALL WORK\project_SQL+DB\.venv\Lib\site-packages\mysql\connector\connection_cext.py", line 781, in cmd_query
    raise get_mysql_exception(
        err.errno, msg=err.msg, sqlstate=err.sqlstate
    ) from err
mysql.connector.errors.IntegrityError: 1452 (23000): Cannot add or update a child row: a foreign key constraint fails (`test_db`.`orders`, CONSTRAINT `fk_orders_cart` FOREIGN KEY (`product_id`) REFERENCES `inventory` (`id`))
2025-07-21 22:43:40,321 - WARNING - Order not found for user 84029 and inventory 5
2025-07-21 22:43:40,327 - ERROR - Error inserting order items for order None: 1452 (23000): Cannot add or update a child row: a foreign key constraint fails (`test_db`.`order_items`, CONSTRAINT `fk_orders_order` FOREIGN KEY (`product_id`) REFERENCES `inventory` (`id`))
Traceback (most recent call last):
  File "C:\Users\mnarv\OneDrive\Desktop\ALL WORK\project_SQL+DB\.venv\Lib\site-packages\mysql\connector\connection_cext.py", line 772, in cmd_query
    self._cmysql.query(
    ~~~~~~~~~~~~~~~~~~^
        query,
        ^^^^^^
    ...<3 lines>...
        query_attrs=self.query_attrs,
        ^^^^^^^^^^^^^^^^^^^^^^^^^^^^^
    )
    ^
_mysql_connector.MySQLInterfaceError: Cannot add or update a child row: a foreign key constraint fails (`test_db`.`order_items`, CONSTRAINT `fk_orders_order` FOREIGN KEY (`product_id`) REFERENCES `inventory` (`id`))

The above exception was the direct cause of the following exception:

Traceback (most recent call last):
  File "c:\Users\mnarv\OneDrive\Desktop\ALL WORK\project_SQL+DB\model\order_model.py", line 73, in order_items
    cursor.execute(
    ~~~~~~~~~~~~~~^
        "INSERT INTO order_items (order_id, product_id, quantity, product_size, product_color, product_quality, product_price, product_name) VALUES (%s, %s, %s, %s, %s, %s, %s, %s)",
        ^^^^^^^^^^^^^^^^^^^^^^^^^^^^^^^^^^^^^^^^^^^^^^^^^^^^^^^^^^^^^^^^^^^^^^^^^^^^^^^^^^^^^^^^^^^^^^^^^^^^^^^^^^^^^^^^^^^^^^^^^^^^^^^^^^^^^^^^^^^^^^^^^^^^^^^^^^^^^^^^^^^^^^^^^^^^^^
        (order_id, product_id, quantity, size, color, quality, product_price, product_name)
        ^^^^^^^^^^^^^^^^^^^^^^^^^^^^^^^^^^^^^^^^^^^^^^^^^^^^^^^^^^^^^^^^^^^^^^^^^^^^^^^^^^^
    )
    ^
  File "C:\Users\mnarv\OneDrive\Desktop\ALL WORK\project_SQL+DB\.venv\Lib\site-packages\mysql\connector\cursor_cext.py", line 356, in execute
    self._connection.cmd_query(
    ~~~~~~~~~~~~~~~~~~~~~~~~~~^
        self._stmt_partition["mappable_stmt"],
        ^^^^^^^^^^^^^^^^^^^^^^^^^^^^^^^^^^^^^^
    ...<2 lines>...
        raw_as_string=self._raw_as_string,
        ^^^^^^^^^^^^^^^^^^^^^^^^^^^^^^^^^^
    )
    ^
  File "C:\Users\mnarv\OneDrive\Desktop\ALL WORK\project_SQL+DB\.venv\Lib\site-packages\mysql\connector\opentelemetry\context_propagation.py", line 97, in wrapper
    return method(cnx, *args, **kwargs)
  File "C:\Users\mnarv\OneDrive\Desktop\ALL WORK\project_SQL+DB\.venv\Lib\site-packages\mysql\connector\connection_cext.py", line 781, in cmd_query
    raise get_mysql_exception(
        err.errno, msg=err.msg, sqlstate=err.sqlstate
    ) from err
mysql.connector.errors.IntegrityError: 1452 (23000): Cannot add or update a child row: a foreign key constraint fails (`test_db`.`order_items`, CONSTRAINT `fk_orders_order` FOREIGN KEY (`product_id`) REFERENCES `inventory` (`id`))
2025-07-22 09:55:25,472 - INFO - User found for email: aayanali1208@gmail.com
2025-07-22 09:55:46,554 - INFO - User found for email: aayanali1208@gmail.com
2025-07-22 09:55:47,338 - INFO - User ID found for email: aayanali1208@gmail.com
2025-07-22 09:55:59,353 - INFO - User found for email: aayanali1208@gmail.com
2025-07-22 09:56:00,281 - ERROR - Error inserting order for 84029: 1452 (23000): Cannot add or update a child row: a foreign key constraint fails (`test_db`.`orders`, CONSTRAINT `fk_orders_cart` FOREIGN KEY (`product_id`) REFERENCES `inventory` (`id`))
Traceback (most recent call last):
  File "C:\Users\mnarv\OneDrive\Desktop\ALL WORK\project_SQL+DB\.venv\Lib\site-packages\mysql\connector\connection_cext.py", line 772, in cmd_query
    self._cmysql.query(
    ~~~~~~~~~~~~~~~~~~^
        query,
        ^^^^^^
    ...<3 lines>...
        query_attrs=self.query_attrs,
        ^^^^^^^^^^^^^^^^^^^^^^^^^^^^^
    )
    ^
_mysql_connector.MySQLInterfaceError: Cannot add or update a child row: a foreign key constraint fails (`test_db`.`orders`, CONSTRAINT `fk_orders_cart` FOREIGN KEY (`product_id`) REFERENCES `inventory` (`id`))

The above exception was the direct cause of the following exception:

Traceback (most recent call last):
  File "c:\Users\mnarv\OneDrive\Desktop\ALL WORK\project_SQL+DB\model\order_model.py", line 27, in insert_order
    cursor.execute(
    ~~~~~~~~~~~~~~^
        "INSERT INTO orders (user_id, product_id, address, city, country, zipcode, phone_number) VALUES (%s, %s, %s, %s, %s, %s, %s)",
        ^^^^^^^^^^^^^^^^^^^^^^^^^^^^^^^^^^^^^^^^^^^^^^^^^^^^^^^^^^^^^^^^^^^^^^^^^^^^^^^^^^^^^^^^^^^^^^^^^^^^^^^^^^^^^^^^^^^^^^^^^^^^^^
        (user_id, product_id, address, city, country, zipcode, phone_number)
        ^^^^^^^^^^^^^^^^^^^^^^^^^^^^^^^^^^^^^^^^^^^^^^^^^^^^^^^^^^^^^^^^^^^^
    )
    ^
  File "C:\Users\mnarv\OneDrive\Desktop\ALL WORK\project_SQL+DB\.venv\Lib\site-packages\mysql\connector\cursor_cext.py", line 356, in execute
    self._connection.cmd_query(
    ~~~~~~~~~~~~~~~~~~~~~~~~~~^
        self._stmt_partition["mappable_stmt"],
        ^^^^^^^^^^^^^^^^^^^^^^^^^^^^^^^^^^^^^^
    ...<2 lines>...
        raw_as_string=self._raw_as_string,
        ^^^^^^^^^^^^^^^^^^^^^^^^^^^^^^^^^^
    )
    ^
  File "C:\Users\mnarv\OneDrive\Desktop\ALL WORK\project_SQL+DB\.venv\Lib\site-packages\mysql\connector\opentelemetry\context_propagation.py", line 97, in wrapper
    return method(cnx, *args, **kwargs)
  File "C:\Users\mnarv\OneDrive\Desktop\ALL WORK\project_SQL+DB\.venv\Lib\site-packages\mysql\connector\connection_cext.py", line 781, in cmd_query
    raise get_mysql_exception(
        err.errno, msg=err.msg, sqlstate=err.sqlstate
    ) from err
mysql.connector.errors.IntegrityError: 1452 (23000): Cannot add or update a child row: a foreign key constraint fails (`test_db`.`orders`, CONSTRAINT `fk_orders_cart` FOREIGN KEY (`product_id`) REFERENCES `inventory` (`id`))
2025-07-22 09:56:00,330 - WARNING - Order not found for user 84029 and inventory 5
2025-07-22 09:56:00,355 - ERROR - Error inserting order items for order None: 1452 (23000): Cannot add or update a child row: a foreign key constraint fails (`test_db`.`order_items`, CONSTRAINT `fk_orders_order` FOREIGN KEY (`product_id`) REFERENCES `inventory` (`id`))
Traceback (most recent call last):
  File "C:\Users\mnarv\OneDrive\Desktop\ALL WORK\project_SQL+DB\.venv\Lib\site-packages\mysql\connector\connection_cext.py", line 772, in cmd_query
    self._cmysql.query(
    ~~~~~~~~~~~~~~~~~~^
        query,
        ^^^^^^
    ...<3 lines>...
        query_attrs=self.query_attrs,
        ^^^^^^^^^^^^^^^^^^^^^^^^^^^^^
    )
    ^
_mysql_connector.MySQLInterfaceError: Cannot add or update a child row: a foreign key constraint fails (`test_db`.`order_items`, CONSTRAINT `fk_orders_order` FOREIGN KEY (`product_id`) REFERENCES `inventory` (`id`))

The above exception was the direct cause of the following exception:

Traceback (most recent call last):
  File "c:\Users\mnarv\OneDrive\Desktop\ALL WORK\project_SQL+DB\model\order_model.py", line 73, in order_items
    cursor.execute(
    ~~~~~~~~~~~~~~^
        "INSERT INTO order_items (order_id, product_id, quantity, product_size, product_color, product_quality, product_price, product_name) VALUES (%s, %s, %s, %s, %s, %s, %s, %s)",
        ^^^^^^^^^^^^^^^^^^^^^^^^^^^^^^^^^^^^^^^^^^^^^^^^^^^^^^^^^^^^^^^^^^^^^^^^^^^^^^^^^^^^^^^^^^^^^^^^^^^^^^^^^^^^^^^^^^^^^^^^^^^^^^^^^^^^^^^^^^^^^^^^^^^^^^^^^^^^^^^^^^^^^^^^^^^^^^
        (order_id, product_id, quantity, size, color, quality, product_price, product_name)
        ^^^^^^^^^^^^^^^^^^^^^^^^^^^^^^^^^^^^^^^^^^^^^^^^^^^^^^^^^^^^^^^^^^^^^^^^^^^^^^^^^^^
    )
    ^
  File "C:\Users\mnarv\OneDrive\Desktop\ALL WORK\project_SQL+DB\.venv\Lib\site-packages\mysql\connector\cursor_cext.py", line 356, in execute
    self._connection.cmd_query(
    ~~~~~~~~~~~~~~~~~~~~~~~~~~^
        self._stmt_partition["mappable_stmt"],
        ^^^^^^^^^^^^^^^^^^^^^^^^^^^^^^^^^^^^^^
    ...<2 lines>...
        raw_as_string=self._raw_as_string,
        ^^^^^^^^^^^^^^^^^^^^^^^^^^^^^^^^^^
    )
    ^
  File "C:\Users\mnarv\OneDrive\Desktop\ALL WORK\project_SQL+DB\.venv\Lib\site-packages\mysql\connector\opentelemetry\context_propagation.py", line 97, in wrapper
    return method(cnx, *args, **kwargs)
  File "C:\Users\mnarv\OneDrive\Desktop\ALL WORK\project_SQL+DB\.venv\Lib\site-packages\mysql\connector\connection_cext.py", line 781, in cmd_query
    raise get_mysql_exception(
        err.errno, msg=err.msg, sqlstate=err.sqlstate
    ) from err
mysql.connector.errors.IntegrityError: 1452 (23000): Cannot add or update a child row: a foreign key constraint fails (`test_db`.`order_items`, CONSTRAINT `fk_orders_order` FOREIGN KEY (`product_id`) REFERENCES `inventory` (`id`))
2025-07-22 10:02:57,736 - INFO - User found for email: aayanali1208@gmail.com
2025-07-22 10:02:58,129 - ERROR - Error inserting order for 84029: 1452 (23000): Cannot add or update a child row: a foreign key constraint fails (`test_db`.`orders`, CONSTRAINT `fk_orders_cart` FOREIGN KEY (`product_id`) REFERENCES `inventory` (`id`))
Traceback (most recent call last):
  File "C:\Users\mnarv\OneDrive\Desktop\ALL WORK\project_SQL+DB\.venv\Lib\site-packages\mysql\connector\connection_cext.py", line 772, in cmd_query
    self._cmysql.query(
    ~~~~~~~~~~~~~~~~~~^
        query,
        ^^^^^^
    ...<3 lines>...
        query_attrs=self.query_attrs,
        ^^^^^^^^^^^^^^^^^^^^^^^^^^^^^
    )
    ^
_mysql_connector.MySQLInterfaceError: Cannot add or update a child row: a foreign key constraint fails (`test_db`.`orders`, CONSTRAINT `fk_orders_cart` FOREIGN KEY (`product_id`) REFERENCES `inventory` (`id`))

The above exception was the direct cause of the following exception:

Traceback (most recent call last):
  File "c:\Users\mnarv\OneDrive\Desktop\ALL WORK\project_SQL+DB\model\order_model.py", line 27, in insert_order
    cursor.execute(
    ~~~~~~~~~~~~~~^
        "INSERT INTO orders (user_id, product_id, address, city, country, zipcode, phone_number) VALUES (%s, %s, %s, %s, %s, %s, %s)",
        ^^^^^^^^^^^^^^^^^^^^^^^^^^^^^^^^^^^^^^^^^^^^^^^^^^^^^^^^^^^^^^^^^^^^^^^^^^^^^^^^^^^^^^^^^^^^^^^^^^^^^^^^^^^^^^^^^^^^^^^^^^^^^^
        (user_id, product_id, address, city, country, zipcode, phone_number)
        ^^^^^^^^^^^^^^^^^^^^^^^^^^^^^^^^^^^^^^^^^^^^^^^^^^^^^^^^^^^^^^^^^^^^
    )
    ^
  File "C:\Users\mnarv\OneDrive\Desktop\ALL WORK\project_SQL+DB\.venv\Lib\site-packages\mysql\connector\cursor_cext.py", line 356, in execute
    self._connection.cmd_query(
    ~~~~~~~~~~~~~~~~~~~~~~~~~~^
        self._stmt_partition["mappable_stmt"],
        ^^^^^^^^^^^^^^^^^^^^^^^^^^^^^^^^^^^^^^
    ...<2 lines>...
        raw_as_string=self._raw_as_string,
        ^^^^^^^^^^^^^^^^^^^^^^^^^^^^^^^^^^
    )
    ^
  File "C:\Users\mnarv\OneDrive\Desktop\ALL WORK\project_SQL+DB\.venv\Lib\site-packages\mysql\connector\opentelemetry\context_propagation.py", line 97, in wrapper
    return method(cnx, *args, **kwargs)
  File "C:\Users\mnarv\OneDrive\Desktop\ALL WORK\project_SQL+DB\.venv\Lib\site-packages\mysql\connector\connection_cext.py", line 781, in cmd_query
    raise get_mysql_exception(
        err.errno, msg=err.msg, sqlstate=err.sqlstate
    ) from err
mysql.connector.errors.IntegrityError: 1452 (23000): Cannot add or update a child row: a foreign key constraint fails (`test_db`.`orders`, CONSTRAINT `fk_orders_cart` FOREIGN KEY (`product_id`) REFERENCES `inventory` (`id`))
2025-07-22 10:19:00,962 - INFO - User found for email: aayanali1208@gmail.com
2025-07-22 10:19:01,322 - ERROR - Error inserting order for 84029: 1452 (23000): Cannot add or update a child row: a foreign key constraint fails (`test_db`.`orders`, CONSTRAINT `fk_orders_product` FOREIGN KEY (`product_id`) REFERENCES `inventory` (`id`))
Traceback (most recent call last):
  File "C:\Users\mnarv\OneDrive\Desktop\ALL WORK\project_SQL+DB\.venv\Lib\site-packages\mysql\connector\connection_cext.py", line 772, in cmd_query
    self._cmysql.query(
    ~~~~~~~~~~~~~~~~~~^
        query,
        ^^^^^^
    ...<3 lines>...
        query_attrs=self.query_attrs,
        ^^^^^^^^^^^^^^^^^^^^^^^^^^^^^
    )
    ^
_mysql_connector.MySQLInterfaceError: Cannot add or update a child row: a foreign key constraint fails (`test_db`.`orders`, CONSTRAINT `fk_orders_product` FOREIGN KEY (`product_id`) REFERENCES `inventory` (`id`))

The above exception was the direct cause of the following exception:

Traceback (most recent call last):
  File "c:\Users\mnarv\OneDrive\Desktop\ALL WORK\project_SQL+DB\model\order_model.py", line 27, in insert_order
    cursor.execute(
    ~~~~~~~~~~~~~~^
        "INSERT INTO orders (user_id, product_id, address, city, country, zipcode, phone_number) VALUES (%s, %s, %s, %s, %s, %s, %s)",
        ^^^^^^^^^^^^^^^^^^^^^^^^^^^^^^^^^^^^^^^^^^^^^^^^^^^^^^^^^^^^^^^^^^^^^^^^^^^^^^^^^^^^^^^^^^^^^^^^^^^^^^^^^^^^^^^^^^^^^^^^^^^^^^
        (user_id, product_id, address, city, country, zipcode, phone_number)
        ^^^^^^^^^^^^^^^^^^^^^^^^^^^^^^^^^^^^^^^^^^^^^^^^^^^^^^^^^^^^^^^^^^^^
    )
    ^
  File "C:\Users\mnarv\OneDrive\Desktop\ALL WORK\project_SQL+DB\.venv\Lib\site-packages\mysql\connector\cursor_cext.py", line 356, in execute
    self._connection.cmd_query(
    ~~~~~~~~~~~~~~~~~~~~~~~~~~^
        self._stmt_partition["mappable_stmt"],
        ^^^^^^^^^^^^^^^^^^^^^^^^^^^^^^^^^^^^^^
    ...<2 lines>...
        raw_as_string=self._raw_as_string,
        ^^^^^^^^^^^^^^^^^^^^^^^^^^^^^^^^^^
    )
    ^
  File "C:\Users\mnarv\OneDrive\Desktop\ALL WORK\project_SQL+DB\.venv\Lib\site-packages\mysql\connector\opentelemetry\context_propagation.py", line 97, in wrapper
    return method(cnx, *args, **kwargs)
  File "C:\Users\mnarv\OneDrive\Desktop\ALL WORK\project_SQL+DB\.venv\Lib\site-packages\mysql\connector\connection_cext.py", line 781, in cmd_query
    raise get_mysql_exception(
        err.errno, msg=err.msg, sqlstate=err.sqlstate
    ) from err
mysql.connector.errors.IntegrityError: 1452 (23000): Cannot add or update a child row: a foreign key constraint fails (`test_db`.`orders`, CONSTRAINT `fk_orders_product` FOREIGN KEY (`product_id`) REFERENCES `inventory` (`id`))
2025-07-22 10:34:19,825 - INFO - User found for email: aayanali1208@gmail.com
2025-07-22 10:34:30,608 - INFO - User found for email: aayanali1208@gmail.com
2025-07-22 10:34:34,474 - INFO - User found for email: aayanali1208@gmail.com
2025-07-22 10:34:35,257 - INFO - User ID found for email: aayanali1208@gmail.com
2025-07-22 10:34:51,917 - INFO - User found for email: aayanali1208@gmail.com
2025-07-22 10:34:52,761 - ERROR - Error inserting order for 84029: 1452 (23000): Cannot add or update a child row: a foreign key constraint fails (`test_db`.`orders`, CONSTRAINT `fk_orders_product` FOREIGN KEY (`product_id`) REFERENCES `inventory` (`id`))
Traceback (most recent call last):
  File "C:\Users\mnarv\OneDrive\Desktop\ALL WORK\project_SQL+DB\.venv\Lib\site-packages\mysql\connector\connection_cext.py", line 772, in cmd_query
    self._cmysql.query(
    ~~~~~~~~~~~~~~~~~~^
        query,
        ^^^^^^
    ...<3 lines>...
        query_attrs=self.query_attrs,
        ^^^^^^^^^^^^^^^^^^^^^^^^^^^^^
    )
    ^
_mysql_connector.MySQLInterfaceError: Cannot add or update a child row: a foreign key constraint fails (`test_db`.`orders`, CONSTRAINT `fk_orders_product` FOREIGN KEY (`product_id`) REFERENCES `inventory` (`id`))

The above exception was the direct cause of the following exception:

Traceback (most recent call last):
  File "c:\Users\mnarv\OneDrive\Desktop\ALL WORK\project_SQL+DB\model\order_model.py", line 27, in insert_order
    cursor.execute(
    ~~~~~~~~~~~~~~^
        "INSERT INTO orders (user_id, product_id, address, city, country, zipcode, phone_number) VALUES (%s, %s, %s, %s, %s, %s, %s)",
        ^^^^^^^^^^^^^^^^^^^^^^^^^^^^^^^^^^^^^^^^^^^^^^^^^^^^^^^^^^^^^^^^^^^^^^^^^^^^^^^^^^^^^^^^^^^^^^^^^^^^^^^^^^^^^^^^^^^^^^^^^^^^^^
        (user_id, product_id, address, city, country, zipcode, phone_number)
        ^^^^^^^^^^^^^^^^^^^^^^^^^^^^^^^^^^^^^^^^^^^^^^^^^^^^^^^^^^^^^^^^^^^^
    )
    ^
  File "C:\Users\mnarv\OneDrive\Desktop\ALL WORK\project_SQL+DB\.venv\Lib\site-packages\mysql\connector\cursor_cext.py", line 356, in execute
    self._connection.cmd_query(
    ~~~~~~~~~~~~~~~~~~~~~~~~~~^
        self._stmt_partition["mappable_stmt"],
        ^^^^^^^^^^^^^^^^^^^^^^^^^^^^^^^^^^^^^^
    ...<2 lines>...
        raw_as_string=self._raw_as_string,
        ^^^^^^^^^^^^^^^^^^^^^^^^^^^^^^^^^^
    )
    ^
  File "C:\Users\mnarv\OneDrive\Desktop\ALL WORK\project_SQL+DB\.venv\Lib\site-packages\mysql\connector\opentelemetry\context_propagation.py", line 97, in wrapper
    return method(cnx, *args, **kwargs)
  File "C:\Users\mnarv\OneDrive\Desktop\ALL WORK\project_SQL+DB\.venv\Lib\site-packages\mysql\connector\connection_cext.py", line 781, in cmd_query
    raise get_mysql_exception(
        err.errno, msg=err.msg, sqlstate=err.sqlstate
    ) from err
mysql.connector.errors.IntegrityError: 1452 (23000): Cannot add or update a child row: a foreign key constraint fails (`test_db`.`orders`, CONSTRAINT `fk_orders_product` FOREIGN KEY (`product_id`) REFERENCES `inventory` (`id`))
2025-07-22 10:39:02,744 - INFO - User found for email: aayanali1208@gmail.com
2025-07-22 10:39:03,827 - ERROR - Error inserting order items for order None: 1452 (23000): Cannot add or update a child row: a foreign key constraint fails (`test_db`.`order_items`, CONSTRAINT `fk_orders_order` FOREIGN KEY (`product_id`) REFERENCES `inventory` (`id`))
Traceback (most recent call last):
  File "C:\Users\mnarv\OneDrive\Desktop\ALL WORK\project_SQL+DB\.venv\Lib\site-packages\mysql\connector\connection_cext.py", line 772, in cmd_query
    self._cmysql.query(
    ~~~~~~~~~~~~~~~~~~^
        query,
        ^^^^^^
    ...<3 lines>...
        query_attrs=self.query_attrs,
        ^^^^^^^^^^^^^^^^^^^^^^^^^^^^^
    )
    ^
_mysql_connector.MySQLInterfaceError: Cannot add or update a child row: a foreign key constraint fails (`test_db`.`order_items`, CONSTRAINT `fk_orders_order` FOREIGN KEY (`product_id`) REFERENCES `inventory` (`id`))

The above exception was the direct cause of the following exception:

Traceback (most recent call last):
  File "c:\Users\mnarv\OneDrive\Desktop\ALL WORK\project_SQL+DB\model\order_model.py", line 71, in order_items
    cursor.execute(
    ~~~~~~~~~~~~~~^
        "INSERT INTO order_items (order_id, product_id, quantity, product_size, product_color, product_quality, product_price, product_name) VALUES (%s, %s, %s, %s, %s, %s, %s, %s)",
        ^^^^^^^^^^^^^^^^^^^^^^^^^^^^^^^^^^^^^^^^^^^^^^^^^^^^^^^^^^^^^^^^^^^^^^^^^^^^^^^^^^^^^^^^^^^^^^^^^^^^^^^^^^^^^^^^^^^^^^^^^^^^^^^^^^^^^^^^^^^^^^^^^^^^^^^^^^^^^^^^^^^^^^^^^^^^^^
        (order_id, product_id, quantity, size, color, quality, product_price, product_name)
        ^^^^^^^^^^^^^^^^^^^^^^^^^^^^^^^^^^^^^^^^^^^^^^^^^^^^^^^^^^^^^^^^^^^^^^^^^^^^^^^^^^^
    )
    ^
  File "C:\Users\mnarv\OneDrive\Desktop\ALL WORK\project_SQL+DB\.venv\Lib\site-packages\mysql\connector\cursor_cext.py", line 356, in execute
    self._connection.cmd_query(
    ~~~~~~~~~~~~~~~~~~~~~~~~~~^
        self._stmt_partition["mappable_stmt"],
        ^^^^^^^^^^^^^^^^^^^^^^^^^^^^^^^^^^^^^^
    ...<2 lines>...
        raw_as_string=self._raw_as_string,
        ^^^^^^^^^^^^^^^^^^^^^^^^^^^^^^^^^^
    )
    ^
  File "C:\Users\mnarv\OneDrive\Desktop\ALL WORK\project_SQL+DB\.venv\Lib\site-packages\mysql\connector\opentelemetry\context_propagation.py", line 97, in wrapper
    return method(cnx, *args, **kwargs)
  File "C:\Users\mnarv\OneDrive\Desktop\ALL WORK\project_SQL+DB\.venv\Lib\site-packages\mysql\connector\connection_cext.py", line 781, in cmd_query
    raise get_mysql_exception(
        err.errno, msg=err.msg, sqlstate=err.sqlstate
    ) from err
mysql.connector.errors.IntegrityError: 1452 (23000): Cannot add or update a child row: a foreign key constraint fails (`test_db`.`order_items`, CONSTRAINT `fk_orders_order` FOREIGN KEY (`product_id`) REFERENCES `inventory` (`id`))
2025-07-22 10:42:14,461 - INFO - User found for email: aayanali1208@gmail.com
2025-07-22 10:54:07,047 - INFO - User found for email: aayanali1208@gmail.com
2025-07-22 10:54:08,024 - INFO - User ID found for email: aayanali1208@gmail.com
2025-07-22 10:56:49,281 - INFO - User found for email: aayanali1208@gmail.com
2025-07-22 10:56:49,286 - INFO - Product ID exists: 3
2025-07-22 10:57:27,165 - INFO - User found for email: aayanali1208@gmail.com
2025-07-22 10:57:27,173 - INFO - Product ID exists: 3
2025-07-22 10:57:56,854 - INFO - User found for email: aayanali1208@gmail.com
2025-07-22 10:57:56,860 - INFO - Product ID exists: 5
2025-07-22 10:58:04,322 - INFO - User found for email: aayanali1208@gmail.com
2025-07-22 10:59:00,370 - INFO - User found for email: aayanali1208@gmail.com
2025-07-22 10:59:01,064 - ERROR - Error inserting order items for order None: 1265 (01000): Data truncated for column 'product_size' at row 1
Traceback (most recent call last):
  File "C:\Users\mnarv\OneDrive\Desktop\ALL WORK\project_SQL+DB\.venv\Lib\site-packages\mysql\connector\connection_cext.py", line 772, in cmd_query
    self._cmysql.query(
    ~~~~~~~~~~~~~~~~~~^
        query,
        ^^^^^^
    ...<3 lines>...
        query_attrs=self.query_attrs,
        ^^^^^^^^^^^^^^^^^^^^^^^^^^^^^
    )
    ^
_mysql_connector.MySQLInterfaceError: Data truncated for column 'product_size' at row 1

The above exception was the direct cause of the following exception:

Traceback (most recent call last):
  File "c:\Users\mnarv\OneDrive\Desktop\ALL WORK\project_SQL+DB\model\order_model.py", line 71, in order_items
    cursor.execute(
    ~~~~~~~~~~~~~~^
        "INSERT INTO order_items (order_id, product_id, quantity, product_size, product_color, product_quality, product_price, product_name) VALUES (%s, %s, %s, %s, %s, %s, %s, %s)",
        ^^^^^^^^^^^^^^^^^^^^^^^^^^^^^^^^^^^^^^^^^^^^^^^^^^^^^^^^^^^^^^^^^^^^^^^^^^^^^^^^^^^^^^^^^^^^^^^^^^^^^^^^^^^^^^^^^^^^^^^^^^^^^^^^^^^^^^^^^^^^^^^^^^^^^^^^^^^^^^^^^^^^^^^^^^^^^^
        (order_id, product_id, quantity, size, color, quality, product_price, product_name)
        ^^^^^^^^^^^^^^^^^^^^^^^^^^^^^^^^^^^^^^^^^^^^^^^^^^^^^^^^^^^^^^^^^^^^^^^^^^^^^^^^^^^
    )
    ^
  File "C:\Users\mnarv\OneDrive\Desktop\ALL WORK\project_SQL+DB\.venv\Lib\site-packages\mysql\connector\cursor_cext.py", line 356, in execute
    self._connection.cmd_query(
    ~~~~~~~~~~~~~~~~~~~~~~~~~~^
        self._stmt_partition["mappable_stmt"],
        ^^^^^^^^^^^^^^^^^^^^^^^^^^^^^^^^^^^^^^
    ...<2 lines>...
        raw_as_string=self._raw_as_string,
        ^^^^^^^^^^^^^^^^^^^^^^^^^^^^^^^^^^
    )
    ^
  File "C:\Users\mnarv\OneDrive\Desktop\ALL WORK\project_SQL+DB\.venv\Lib\site-packages\mysql\connector\opentelemetry\context_propagation.py", line 97, in wrapper
    return method(cnx, *args, **kwargs)
  File "C:\Users\mnarv\OneDrive\Desktop\ALL WORK\project_SQL+DB\.venv\Lib\site-packages\mysql\connector\connection_cext.py", line 781, in cmd_query
    raise get_mysql_exception(
        err.errno, msg=err.msg, sqlstate=err.sqlstate
    ) from err
mysql.connector.errors.DatabaseError: 1265 (01000): Data truncated for column 'product_size' at row 1
2025-07-22 11:00:07,316 - INFO - User found for email: aayanali1208@gmail.com
2025-07-22 11:00:07,320 - INFO - Product ID exists: 5
2025-07-22 11:00:32,555 - INFO - User found for email: aayanali1208@gmail.com
2025-07-22 11:00:32,557 - INFO - Product ID exists: 3
2025-07-22 11:00:42,092 - INFO - User found for email: aayanali1208@gmail.com
2025-07-22 11:02:51,458 - INFO - User found for email: aayanali1208@gmail.com
2025-07-22 11:02:52,029 - ERROR - Error inserting order items for order None: 1265 (01000): Data truncated for column 'product_quality' at row 1
Traceback (most recent call last):
  File "C:\Users\mnarv\OneDrive\Desktop\ALL WORK\project_SQL+DB\.venv\Lib\site-packages\mysql\connector\connection_cext.py", line 772, in cmd_query
    self._cmysql.query(
    ~~~~~~~~~~~~~~~~~~^
        query,
        ^^^^^^
    ...<3 lines>...
        query_attrs=self.query_attrs,
        ^^^^^^^^^^^^^^^^^^^^^^^^^^^^^
    )
    ^
_mysql_connector.MySQLInterfaceError: Data truncated for column 'product_quality' at row 1

The above exception was the direct cause of the following exception:

Traceback (most recent call last):
  File "c:\Users\mnarv\OneDrive\Desktop\ALL WORK\project_SQL+DB\model\order_model.py", line 71, in order_items
    cursor.execute(
    ~~~~~~~~~~~~~~^
        "INSERT INTO order_items (order_id, product_id, quantity, product_size, product_color, product_quality, product_price, product_name) VALUES (%s, %s, %s, %s, %s, %s, %s, %s)",
        ^^^^^^^^^^^^^^^^^^^^^^^^^^^^^^^^^^^^^^^^^^^^^^^^^^^^^^^^^^^^^^^^^^^^^^^^^^^^^^^^^^^^^^^^^^^^^^^^^^^^^^^^^^^^^^^^^^^^^^^^^^^^^^^^^^^^^^^^^^^^^^^^^^^^^^^^^^^^^^^^^^^^^^^^^^^^^^
        (order_id, product_id, quantity, size, color, quality, product_price, product_name)
        ^^^^^^^^^^^^^^^^^^^^^^^^^^^^^^^^^^^^^^^^^^^^^^^^^^^^^^^^^^^^^^^^^^^^^^^^^^^^^^^^^^^
    )
    ^
  File "C:\Users\mnarv\OneDrive\Desktop\ALL WORK\project_SQL+DB\.venv\Lib\site-packages\mysql\connector\cursor_cext.py", line 356, in execute
    self._connection.cmd_query(
    ~~~~~~~~~~~~~~~~~~~~~~~~~~^
        self._stmt_partition["mappable_stmt"],
        ^^^^^^^^^^^^^^^^^^^^^^^^^^^^^^^^^^^^^^
    ...<2 lines>...
        raw_as_string=self._raw_as_string,
        ^^^^^^^^^^^^^^^^^^^^^^^^^^^^^^^^^^
    )
    ^
  File "C:\Users\mnarv\OneDrive\Desktop\ALL WORK\project_SQL+DB\.venv\Lib\site-packages\mysql\connector\opentelemetry\context_propagation.py", line 97, in wrapper
    return method(cnx, *args, **kwargs)
  File "C:\Users\mnarv\OneDrive\Desktop\ALL WORK\project_SQL+DB\.venv\Lib\site-packages\mysql\connector\connection_cext.py", line 781, in cmd_query
    raise get_mysql_exception(
        err.errno, msg=err.msg, sqlstate=err.sqlstate
    ) from err
mysql.connector.errors.DatabaseError: 1265 (01000): Data truncated for column 'product_quality' at row 1
2025-07-22 11:03:19,159 - INFO - User found for email: aayanali1208@gmail.com
2025-07-22 11:08:49,441 - INFO - User found for email: aayanali1208@gmail.com
2025-07-22 11:09:00,210 - INFO - User found for email: aayanali1208@gmail.com
2025-07-22 11:09:41,418 - INFO - User found for email: aayanali1208@gmail.com
2025-07-22 11:11:16,395 - INFO - User found for email: aayanali1208@gmail.com
2025-07-22 11:13:55,474 - INFO - User found for email: aayanali1208@gmail.com
2025-07-22 11:13:55,487 - WARNING - No orders found for user 84029
2025-07-22 11:15:35,204 - INFO - User found for email: aayanali1208@gmail.com
2025-07-22 11:15:35,216 - WARNING - No orders found for user 84029
2025-07-22 11:17:39,815 - INFO - User found for email: aayanali1208@gmail.com
2025-07-22 11:17:39,821 - WARNING - No orders found for user 84029
2025-07-22 11:26:28,166 - INFO - User found for email: aayanali1208@gmail.com
2025-07-22 11:26:47,831 - INFO - User found for email: aayanali1208@gmail.com
2025-07-22 11:26:51,865 - INFO - User found for email: aayanali1208@gmail.com
2025-07-22 11:26:52,851 - INFO - User ID found for email: aayanali1208@gmail.com
2025-07-22 11:27:07,346 - INFO - User found for email: aayanali1208@gmail.com
2025-07-22 11:27:07,357 - WARNING - No orders found for user 84029
2025-07-22 11:38:34,194 - INFO - User found for email: aayanali1208@gmail.com
2025-07-22 11:38:35,010 - INFO - User ID found for email: aayanali1208@gmail.com
2025-07-22 11:39:46,000 - INFO - User found for email: aayanali1208@gmail.com
2025-07-22 11:39:55,885 - INFO - User found for email: aayanali1208@gmail.com
2025-07-22 11:40:00,241 - INFO - User found for email: aayanali1208@gmail.com
2025-07-22 11:40:07,806 - INFO - User found for email: aayanali1208@gmail.com
2025-07-22 11:40:19,581 - INFO - User found for email: aayanali1208@gmail.com
2025-07-22 11:41:05,891 - INFO - User found for email: aayanali1208@gmail.com
2025-07-22 11:41:05,895 - INFO - Product ID exists: 3
2025-07-22 11:41:49,510 - INFO - User found for email: aayanali1208@gmail.com
2025-07-22 11:41:49,512 - INFO - Product ID exists: 3
2025-07-22 11:42:02,859 - INFO - User found for email: aayanali1208@gmail.com
2025-07-22 11:42:02,862 - INFO - Product ID exists: 3
2025-07-22 11:42:29,956 - INFO - User found for email: aayanali1208@gmail.com
2025-07-22 11:42:29,959 - INFO - Product ID exists: 4
2025-07-22 11:42:37,230 - INFO - User found for email: aayanali1208@gmail.com
2025-07-22 11:43:17,985 - INFO - User found for email: aayanali1208@gmail.com
2025-07-22 11:44:07,006 - INFO - User found for email: aayanali1208@gmail.com
2025-07-22 11:44:07,013 - WARNING - No orders found for user 84029
2025-07-22 11:50:32,643 - INFO - User found for email: aayanali1208@gmail.com
2025-07-22 11:50:32,657 - WARNING - No orders found for user 84029
2025-07-22 11:50:34,770 - INFO - User found for email: aayanali1208@gmail.com
2025-07-22 11:50:34,779 - WARNING - No orders found for user 84029
2025-07-22 11:50:36,053 - INFO - User found for email: aayanali1208@gmail.com
2025-07-22 11:50:36,061 - WARNING - No orders found for user 84029
2025-07-22 11:50:37,032 - INFO - User found for email: aayanali1208@gmail.com
2025-07-22 11:50:37,042 - WARNING - No orders found for user 84029
2025-07-22 11:51:26,079 - INFO - User found for email: aayanali1208@gmail.com
2025-07-22 11:51:26,082 - INFO - Product ID exists: 4
2025-07-22 11:51:32,681 - INFO - User found for email: aayanali1208@gmail.com
2025-07-22 11:51:32,684 - INFO - Product ID exists: 4
2025-07-22 11:51:41,242 - INFO - User found for email: aayanali1208@gmail.com
2025-07-22 11:51:41,245 - INFO - Product ID exists: 4
2025-07-22 11:51:42,303 - INFO - User found for email: aayanali1208@gmail.com
2025-07-22 11:51:42,306 - INFO - Product ID exists: 4
2025-07-22 11:51:53,818 - INFO - User found for email: aayanali1208@gmail.com
2025-07-22 11:51:53,820 - INFO - Product ID exists: 4
2025-07-22 11:51:59,553 - INFO - User found for email: aayanali1208@gmail.com
2025-07-22 11:51:59,555 - INFO - Product ID exists: 4
2025-07-22 11:52:04,792 - INFO - User found for email: aayanali1208@gmail.com
2025-07-22 11:52:04,795 - INFO - Product ID exists: 4
2025-07-22 11:52:42,852 - INFO - User found for email: aayanali1208@gmail.com
2025-07-22 11:52:42,857 - INFO - Product ID exists: 4
2025-07-22 11:53:25,165 - INFO - User found for email: aayanali1208@gmail.com
2025-07-22 11:53:49,374 - INFO - User found for email: aayanali1208@gmail.com
2025-07-22 11:54:26,568 - INFO - User found for email: aayanali1208@gmail.com
2025-07-22 11:55:58,571 - INFO - User found for email: aayanali1208@gmail.com
2025-07-22 11:58:37,271 - INFO - User found for email: aayanali1208@gmail.com
2025-07-22 11:58:37,274 - ERROR - No orders updated for order 3
2025-07-22 11:58:37,274 - ERROR - Error updating order address for order 3: Update failed
Traceback (most recent call last):
  File "c:\Users\mnarv\OneDrive\Desktop\ALL WORK\project_SQL+DB\model\order_model.py", line 143, in update_order_address_model
    raise Exception("Update failed")
Exception: Update failed
2025-07-22 11:58:48,164 - INFO - User found for email: aayanali1208@gmail.com
2025-07-22 11:58:48,167 - ERROR - No orders updated for order 47
2025-07-22 11:58:48,167 - ERROR - Error updating order address for order 47: Update failed
Traceback (most recent call last):
  File "c:\Users\mnarv\OneDrive\Desktop\ALL WORK\project_SQL+DB\model\order_model.py", line 143, in update_order_address_model
    raise Exception("Update failed")
Exception: Update failed
2025-07-22 11:59:56,040 - INFO - User found for email: aayanali1208@gmail.com
2025-07-22 11:59:56,043 - ERROR - No orders updated for order 7
2025-07-22 11:59:56,043 - ERROR - Error updating order address for order 7: Update failed
Traceback (most recent call last):
  File "c:\Users\mnarv\OneDrive\Desktop\ALL WORK\project_SQL+DB\model\order_model.py", line 143, in update_order_address_model
    raise Exception("Update failed")
Exception: Update failed
2025-07-22 12:00:00,599 - INFO - User found for email: aayanali1208@gmail.com
2025-07-22 12:00:00,602 - ERROR - No orders updated for order 4
2025-07-22 12:00:00,602 - ERROR - Error updating order address for order 4: Update failed
Traceback (most recent call last):
  File "c:\Users\mnarv\OneDrive\Desktop\ALL WORK\project_SQL+DB\model\order_model.py", line 143, in update_order_address_model
    raise Exception("Update failed")
Exception: Update failed
2025-07-22 12:01:07,357 - INFO - User found for email: aayanali1208@gmail.com
2025-07-22 12:01:07,361 - ERROR - No orders updated for order 4
2025-07-22 12:01:07,362 - ERROR - Error updating order address for order 4: Update failed
Traceback (most recent call last):
  File "c:\Users\mnarv\OneDrive\Desktop\ALL WORK\project_SQL+DB\model\order_model.py", line 143, in update_order_address_model
    raise Exception("Update failed")
Exception: Update failed
2025-07-22 12:01:09,026 - INFO - User found for email: aayanali1208@gmail.com
2025-07-22 12:01:09,028 - ERROR - No orders updated for order 4
2025-07-22 12:01:09,029 - ERROR - Error updating order address for order 4: Update failed
Traceback (most recent call last):
  File "c:\Users\mnarv\OneDrive\Desktop\ALL WORK\project_SQL+DB\model\order_model.py", line 143, in update_order_address_model
    raise Exception("Update failed")
Exception: Update failed
2025-07-22 12:02:08,097 - INFO - User found for email: aayanali1208@gmail.com
2025-07-22 12:02:08,099 - ERROR - No orders updated for order 4
2025-07-22 12:02:08,099 - ERROR - Error updating order address for order 4: Update failed
Traceback (most recent call last):
  File "c:\Users\mnarv\OneDrive\Desktop\ALL WORK\project_SQL+DB\model\order_model.py", line 143, in update_order_address_model
    raise Exception("Update failed")
Exception: Update failed
2025-07-22 12:03:18,777 - INFO - User found for email: aayanali1208@gmail.com
2025-07-22 12:03:18,778 - INFO - Order address updated for order 4
2025-07-22 12:03:35,157 - INFO - User found for email: aayanali1208@gmail.com
2025-07-22 12:03:35,159 - INFO - Order address updated for order 4
2025-07-22 12:04:57,919 - INFO - User found for email: aayanali1208@gmail.com
2025-07-22 12:04:57,923 - ERROR - No orders updated for order 4
2025-07-22 12:04:57,924 - ERROR - Error updating order address for order 4: Update failed
Traceback (most recent call last):
  File "c:\Users\mnarv\OneDrive\Desktop\ALL WORK\project_SQL+DB\model\order_model.py", line 143, in update_order_address_model
    raise Exception("Update failed")
Exception: Update failed
2025-07-22 12:06:52,579 - INFO - User found for email: aayanali1208@gmail.com
2025-07-22 12:06:52,582 - ERROR - No orders updated for order 4
2025-07-22 12:06:52,582 - ERROR - Error updating order address for order 4: Update failed
Traceback (most recent call last):
  File "c:\Users\mnarv\OneDrive\Desktop\ALL WORK\project_SQL+DB\model\order_model.py", line 143, in update_order_address_model
    raise Exception("Update failed")
Exception: Update failed
2025-07-22 12:08:55,913 - INFO - User found for email: aayanali1208@gmail.com
2025-07-22 12:09:16,150 - INFO - User found for email: aayanali1208@gmail.com
2025-07-22 12:09:21,652 - INFO - User found for email: aayanali1208@gmail.com
2025-07-22 12:09:22,524 - INFO - User ID found for email: aayanali1208@gmail.com
2025-07-22 12:09:35,136 - INFO - User found for email: aayanali1208@gmail.com
2025-07-22 12:09:35,138 - ERROR - Order with id 4 not found for address update
2025-07-22 12:09:35,140 - ERROR - Error updating order address for order 4: Order not found
Traceback (most recent call last):
  File "c:\Users\mnarv\OneDrive\Desktop\ALL WORK\project_SQL+DB\model\order_model.py", line 143, in update_order_address_model
    raise Exception("Order not found")
Exception: Order not found
2025-07-22 12:11:30,694 - INFO - User found for email: aayanali1208@gmail.com
2025-07-22 12:11:30,697 - WARNING - Order ID 4 not found in orders table
2025-07-22 12:11:30,697 - ERROR - Error updating order address for order 4: Order not found
Traceback (most recent call last):
  File "c:\Users\mnarv\OneDrive\Desktop\ALL WORK\project_SQL+DB\model\order_model.py", line 139, in update_order_address_model
    raise Exception("Order not found")
Exception: Order not found
2025-07-22 12:11:41,733 - INFO - User found for email: aayanali1208@gmail.com
2025-07-22 12:11:41,736 - WARNING - Order ID 4 not found in orders table
2025-07-22 12:11:41,736 - ERROR - Error updating order address for order 4: Order not found
Traceback (most recent call last):
  File "c:\Users\mnarv\OneDrive\Desktop\ALL WORK\project_SQL+DB\model\order_model.py", line 139, in update_order_address_model
    raise Exception("Order not found")
Exception: Order not found
2025-07-22 12:11:45,821 - INFO - User found for email: aayanali1208@gmail.com
2025-07-22 12:11:45,823 - WARNING - Order ID 4 not found in orders table
2025-07-22 12:11:45,823 - ERROR - Error updating order address for order 4: Order not foud
Traceback (most recent call last):
  File "c:\Users\mnarv\OneDrive\Desktop\ALL WORK\project_SQL+DB\model\order_model.py", line 139, in update_order_address_model
    raise Exception("Order not foud")
Exception: Order not foud
2025-07-22 12:11:55,976 - INFO - User found for email: aayanali1208@gmail.com
2025-07-22 12:11:55,995 - INFO - Order address updated for order 47
2025-07-22 12:14:32,146 - INFO - User found for email: aayanali1208@gmail.com
2025-07-22 12:14:32,903 - INFO - Product ID exists: 1
2025-07-22 12:14:32,913 - ERROR - No order_items updated for order 47 and inventory 1
2025-07-22 12:14:32,913 - ERROR - Error updating order item for order 47: Update failed
Traceback (most recent call last):
  File "c:\Users\mnarv\OneDrive\Desktop\ALL WORK\project_SQL+DB\model\order_model.py", line 124, in update_order_item_model
    raise Exception("Update failed")
Exception: Update failed
2025-07-22 12:15:46,164 - INFO - User found for email: aayanali1208@gmail.com
2025-07-22 12:15:46,505 - INFO - Product ID exists: 1
2025-07-22 12:15:46,509 - ERROR - Error updating order item for order 47: No result set to fetch from
Traceback (most recent call last):
  File "c:\Users\mnarv\OneDrive\Desktop\ALL WORK\project_SQL+DB\model\order_model.py", line 118, in update_order_item_model
    if not cursor.fetchone():
           ~~~~~~~~~~~~~~~^^
  File "C:\Users\mnarv\OneDrive\Desktop\ALL WORK\project_SQL+DB\.venv\Lib\site-packages\mysql\connector\cursor_cext.py", line 732, in fetchone
    self._check_executed()
    ~~~~~~~~~~~~~~~~~~~~^^
  File "C:\Users\mnarv\OneDrive\Desktop\ALL WORK\project_SQL+DB\.venv\Lib\site-packages\mysql\connector\cursor_cext.py", line 219, in _check_executed
    raise InterfaceError(ERR_NO_RESULT_TO_FETCH)
mysql.connector.errors.InterfaceError: No result set to fetch from
2025-07-22 12:16:41,283 - INFO - User found for email: aayanali1208@gmail.com
2025-07-22 12:16:41,632 - INFO - Product ID exists: 1
2025-07-22 12:16:41,638 - ERROR - Error updating order item for order 47: No result set to fetch from
Traceback (most recent call last):
  File "c:\Users\mnarv\OneDrive\Desktop\ALL WORK\project_SQL+DB\model\order_model.py", line 118, in update_order_item_model
    if not cursor.fetchone():
           ~~~~~~~~~~~~~~~^^
  File "C:\Users\mnarv\OneDrive\Desktop\ALL WORK\project_SQL+DB\.venv\Lib\site-packages\mysql\connector\cursor_cext.py", line 732, in fetchone
    self._check_executed()
    ~~~~~~~~~~~~~~~~~~~~^^
  File "C:\Users\mnarv\OneDrive\Desktop\ALL WORK\project_SQL+DB\.venv\Lib\site-packages\mysql\connector\cursor_cext.py", line 219, in _check_executed
    raise InterfaceError(ERR_NO_RESULT_TO_FETCH)
mysql.connector.errors.InterfaceError: No result set to fetch from
2025-07-22 12:16:54,149 - INFO - User found for email: aayanali1208@gmail.com
2025-07-22 12:16:54,490 - INFO - Product ID exists: 1
2025-07-22 12:16:54,498 - ERROR - No order_items updated for order 47 and inventory 1
2025-07-22 12:16:54,499 - ERROR - Error updating order item for order 47: Update failed
Traceback (most recent call last):
  File "c:\Users\mnarv\OneDrive\Desktop\ALL WORK\project_SQL+DB\model\order_model.py", line 126, in update_order_item_model
    raise Exception("Update failed")
Exception: Update failed
2025-07-22 12:17:16,487 - INFO - User found for email: aayanali1208@gmail.com
2025-07-22 12:17:16,825 - INFO - Product ID exists: 4
2025-07-22 12:17:36,071 - INFO - User found for email: aayanali1208@gmail.com
2025-07-22 12:17:36,409 - INFO - Product ID exists: 4
2025-07-22 12:17:41,600 - INFO - User found for email: aayanali1208@gmail.com
2025-07-22 12:17:41,942 - INFO - Product ID exists: 4
2025-07-22 12:20:03,921 - INFO - User found for email: aayanali1208@gmail.com
2025-07-22 12:20:04,244 - INFO - Product ID exists: 4
2025-07-22 12:20:36,588 - INFO - User found for email: aayanali1208@gmail.com
2025-07-22 12:20:36,933 - INFO - Product ID exists: 4
2025-07-22 12:20:46,783 - INFO - User found for email: aayanali1208@gmail.com
2025-07-22 12:20:47,118 - INFO - Product ID exists: 4
2025-07-22 12:22:16,882 - INFO - User found for email: aayanali1208@gmail.com
2025-07-22 12:22:17,244 - INFO - Product ID exists: 4
2025-07-22 12:22:17,249 - ERROR - No order_items updated for order 47 and inventory 4
2025-07-22 12:22:17,250 - ERROR - Error updating order item for order 47: Update failed
Traceback (most recent call last):
  File "c:\Users\mnarv\OneDrive\Desktop\ALL WORK\project_SQL+DB\model\order_model.py", line 126, in update_order_item_model
    raise Exception("Update failed")
Exception: Update failed
2025-07-22 12:22:33,543 - INFO - User found for email: aayanali1208@gmail.com
2025-07-22 12:22:33,880 - INFO - Product ID exists: 4
2025-07-22 12:22:33,900 - INFO - Order item updated for order 47 and inventory 4
2025-07-22 12:22:53,794 - INFO - User found for email: aayanali1208@gmail.com
2025-07-22 12:22:54,120 - INFO - Product ID exists: 4
2025-07-22 12:22:54,125 - ERROR - No order_items updated for order 47 and inventory 4
2025-07-22 12:22:54,125 - ERROR - Error updating order item for order 47: Update failed
Traceback (most recent call last):
  File "c:\Users\mnarv\OneDrive\Desktop\ALL WORK\project_SQL+DB\model\order_model.py", line 126, in update_order_item_model
    raise Exception("Update failed")
Exception: Update failed
2025-07-22 12:23:08,693 - INFO - User found for email: aayanali1208@gmail.com
2025-07-22 12:23:09,031 - INFO - Product ID exists: 4
2025-07-22 12:23:09,095 - INFO - Order item updated for order 47 and inventory 4
2025-07-22 12:23:38,442 - INFO - User found for email: aayanali1208@gmail.com
2025-07-22 12:23:38,790 - INFO - Product ID exists: 5
2025-07-22 12:23:42,586 - INFO - User found for email: aayanali1208@gmail.com
2025-07-22 12:23:42,895 - INFO - Product ID exists: 5
2025-07-22 12:23:42,900 - ERROR - No order_items updated for order 47 and inventory 5
2025-07-22 12:23:42,900 - ERROR - Error updating order item for order 47: Update failed
Traceback (most recent call last):
  File "c:\Users\mnarv\OneDrive\Desktop\ALL WORK\project_SQL+DB\model\order_model.py", line 126, in update_order_item_model
    raise Exception("Update failed")
Exception: Update failed
2025-07-22 12:23:46,445 - INFO - User found for email: aayanali1208@gmail.com
2025-07-22 12:23:46,761 - INFO - Product ID exists: 5
2025-07-22 12:23:46,766 - ERROR - No order_items updated for order 47 and inventory 5
2025-07-22 12:23:46,766 - ERROR - Error updating order item for order 47: Update failed
Traceback (most recent call last):
  File "c:\Users\mnarv\OneDrive\Desktop\ALL WORK\project_SQL+DB\model\order_model.py", line 126, in update_order_item_model
    raise Exception("Update failed")
Exception: Update failed
2025-07-22 12:24:24,787 - INFO - User found for email: aayanali1208@gmail.com
2025-07-22 12:24:25,130 - INFO - Product ID exists: 5
2025-07-22 12:24:25,136 - ERROR - No order_items updated for order 47 and inventory 5
2025-07-22 12:24:25,137 - ERROR - Error updating order item for order 47: Update failed
Traceback (most recent call last):
  File "c:\Users\mnarv\OneDrive\Desktop\ALL WORK\project_SQL+DB\model\order_model.py", line 126, in update_order_item_model
    raise Exception("Update failed")
Exception: Update failed
2025-07-22 12:24:29,841 - INFO - User found for email: aayanali1208@gmail.com
2025-07-22 12:24:30,178 - INFO - Product ID exists: 5
2025-07-22 12:24:30,184 - ERROR - No order_items updated for order 47 and inventory 5
2025-07-22 12:24:30,185 - ERROR - Error updating order item for order 47: Update failed
Traceback (most recent call last):
  File "c:\Users\mnarv\OneDrive\Desktop\ALL WORK\project_SQL+DB\model\order_model.py", line 126, in update_order_item_model
    raise Exception("Update failed")
Exception: Update failed
2025-07-22 12:24:54,340 - INFO - User found for email: aayanali1208@gmail.com
2025-07-22 12:25:17,668 - INFO - User found for email: aayanali1208@gmail.com
2025-07-22 12:56:02,573 - INFO - User created: Aayan (aayanali1208@gmail.com)
2025-07-22 12:56:47,367 - ERROR - Failed to insert user (aayanali1208@gmail.com): 1062 (23000): Duplicate entry 'aayanali1208@gmail.com' for key 'users.email'
Traceback (most recent call last):
  File "C:\Users\mnarv\OneDrive\Desktop\ALL WORK\project_SQL+DB\.venv\Lib\site-packages\mysql\connector\connection_cext.py", line 772, in cmd_query
    self._cmysql.query(
    ~~~~~~~~~~~~~~~~~~^
        query,
        ^^^^^^
    ...<3 lines>...
        query_attrs=self.query_attrs,
        ^^^^^^^^^^^^^^^^^^^^^^^^^^^^^
    )
    ^
_mysql_connector.MySQLInterfaceError: Duplicate entry 'aayanali1208@gmail.com' for key 'users.email'

The above exception was the direct cause of the following exception:

Traceback (most recent call last):
  File "c:\Users\mnarv\OneDrive\Desktop\ALL WORK\project_SQL+DB\model\user_model.py", line 18, in insert_user
    cursor.execute(
    ~~~~~~~~~~~~~~^
        "INSERT INTO users (username, email, password) VALUES (%s, %s, %s)",
        ^^^^^^^^^^^^^^^^^^^^^^^^^^^^^^^^^^^^^^^^^^^^^^^^^^^^^^^^^^^^^^^^^^^^
        (username, email, password)
        ^^^^^^^^^^^^^^^^^^^^^^^^^^^
    )
    ^
  File "C:\Users\mnarv\OneDrive\Desktop\ALL WORK\project_SQL+DB\.venv\Lib\site-packages\mysql\connector\cursor_cext.py", line 356, in execute
    self._connection.cmd_query(
    ~~~~~~~~~~~~~~~~~~~~~~~~~~^
        self._stmt_partition["mappable_stmt"],
        ^^^^^^^^^^^^^^^^^^^^^^^^^^^^^^^^^^^^^^
    ...<2 lines>...
        raw_as_string=self._raw_as_string,
        ^^^^^^^^^^^^^^^^^^^^^^^^^^^^^^^^^^
    )
    ^
  File "C:\Users\mnarv\OneDrive\Desktop\ALL WORK\project_SQL+DB\.venv\Lib\site-packages\mysql\connector\opentelemetry\context_propagation.py", line 97, in wrapper
    return method(cnx, *args, **kwargs)
  File "C:\Users\mnarv\OneDrive\Desktop\ALL WORK\project_SQL+DB\.venv\Lib\site-packages\mysql\connector\connection_cext.py", line 781, in cmd_query
    raise get_mysql_exception(
        err.errno, msg=err.msg, sqlstate=err.sqlstate
    ) from err
mysql.connector.errors.IntegrityError: 1062 (23000): Duplicate entry 'aayanali1208@gmail.com' for key 'users.email'
2025-07-22 12:57:53,984 - INFO - User found for email: aayanali1208@gmail.com
2025-07-22 12:57:54,395 - INFO - User updated: aayanali1208@gmail.com
2025-07-22 12:58:10,996 - INFO - User found for email: aayanali1208@gmail.com
2025-07-22 12:58:46,677 - INFO - User updated: aayanali1208@gmail.com
2025-07-22 13:47:44,943 - INFO - User found for email: aayanali1208@gmail.com
2025-07-22 13:47:45,267 - INFO - User ID found for email: aayanali1208@gmail.com
2025-07-22 13:49:46,001 - INFO - User found for email: aayanali1208@gmail.com
2025-07-22 13:49:46,003 - INFO - Product ID exists: 3
2025-07-22 13:51:41,135 - INFO - User found for email: aayanali1208@gmail.com
2025-07-22 13:51:50,464 - INFO - User found for email: aayanali1208@gmail.com
2025-07-22 13:52:31,191 - INFO - User found for email: aayanali1208@gmail.com
2025-07-22 13:53:57,492 - INFO - Product ID exists: 4
2025-07-22 13:54:07,529 - INFO - Product ID exists: 4
2025-07-22 13:54:16,574 - INFO - Product ID exists: 4
2025-07-22 13:55:32,598 - INFO - Product ID exists: 4
2025-07-22 13:55:55,743 - INFO - Product ID exists: 4
2025-07-22 13:57:17,525 - INFO - User found for email: aayanali1208@gmail.com
2025-07-22 13:57:27,507 - INFO - Product ID exists: 4
2025-07-22 13:59:40,242 - INFO - Product ID exists: 4
2025-07-22 13:59:40,250 - ERROR - Error updating cart item: 1054 (42S22): Unknown column 'cart_id' in 'where clause'
Traceback (most recent call last):
  File "C:\Users\mnarv\OneDrive\Desktop\ALL WORK\project_SQL+DB\.venv\Lib\site-packages\mysql\connector\connection_cext.py", line 772, in cmd_query
    self._cmysql.query(
    ~~~~~~~~~~~~~~~~~~^
        query,
        ^^^^^^
    ...<3 lines>...
        query_attrs=self.query_attrs,
        ^^^^^^^^^^^^^^^^^^^^^^^^^^^^^
    )
    ^
_mysql_connector.MySQLInterfaceError: Unknown column 'cart_id' in 'where clause'

The above exception was the direct cause of the following exception:

Traceback (most recent call last):
  File "C:\Users\mnarv\OneDrive\Desktop\ALL WORK\project_SQL+DB\model\cart_model.py", line 70, in update_to_cart
    cursor.execute("""
    ~~~~~~~~~~~~~~^^^^
        UPDATE cart_items
        ^^^^^^^^^^^^^^^^^
    ...<5 lines>...
        WHERE cart_id = %s
        ^^^^^^^^^^^^^^^^^^
    """, (quantity, size, color, quality, product_id, cart_id))
    ^^^^^^^^^^^^^^^^^^^^^^^^^^^^^^^^^^^^^^^^^^^^^^^^^^^^^^^^^^^
  File "C:\Users\mnarv\OneDrive\Desktop\ALL WORK\project_SQL+DB\.venv\Lib\site-packages\mysql\connector\cursor_cext.py", line 356, in execute
    self._connection.cmd_query(
    ~~~~~~~~~~~~~~~~~~~~~~~~~~^
        self._stmt_partition["mappable_stmt"],
        ^^^^^^^^^^^^^^^^^^^^^^^^^^^^^^^^^^^^^^
    ...<2 lines>...
        raw_as_string=self._raw_as_string,
        ^^^^^^^^^^^^^^^^^^^^^^^^^^^^^^^^^^
    )
    ^
  File "C:\Users\mnarv\OneDrive\Desktop\ALL WORK\project_SQL+DB\.venv\Lib\site-packages\mysql\connector\opentelemetry\context_propagation.py", line 97, in wrapper
    return method(cnx, *args, **kwargs)
  File "C:\Users\mnarv\OneDrive\Desktop\ALL WORK\project_SQL+DB\.venv\Lib\site-packages\mysql\connector\connection_cext.py", line 781, in cmd_query
    raise get_mysql_exception(
        err.errno, msg=err.msg, sqlstate=err.sqlstate
    ) from err
mysql.connector.errors.ProgrammingError: 1054 (42S22): Unknown column 'cart_id' in 'where clause'
2025-07-22 14:01:06,623 - INFO - Product ID exists: 4
2025-07-22 14:01:06,629 - ERROR - Error updating cart item: 1054 (42S22): Unknown column 'cart_id' in 'where clause'
Traceback (most recent call last):
  File "C:\Users\mnarv\OneDrive\Desktop\ALL WORK\project_SQL+DB\.venv\Lib\site-packages\mysql\connector\connection_cext.py", line 772, in cmd_query
    self._cmysql.query(
    ~~~~~~~~~~~~~~~~~~^
        query,
        ^^^^^^
    ...<3 lines>...
        query_attrs=self.query_attrs,
        ^^^^^^^^^^^^^^^^^^^^^^^^^^^^^
    )
    ^
_mysql_connector.MySQLInterfaceError: Unknown column 'cart_id' in 'where clause'

The above exception was the direct cause of the following exception:

Traceback (most recent call last):
  File "C:\Users\mnarv\OneDrive\Desktop\ALL WORK\project_SQL+DB\model\cart_model.py", line 70, in update_to_cart
    cursor.execute("""
    ~~~~~~~~~~~~~~^^^^
        UPDATE cart_items
        ^^^^^^^^^^^^^^^^^
    ...<5 lines>...
        WHERE cart_id = %s
        ^^^^^^^^^^^^^^^^^^
    """, (quantity, size, color, quality, product_id, cart_id))
    ^^^^^^^^^^^^^^^^^^^^^^^^^^^^^^^^^^^^^^^^^^^^^^^^^^^^^^^^^^^
  File "C:\Users\mnarv\OneDrive\Desktop\ALL WORK\project_SQL+DB\.venv\Lib\site-packages\mysql\connector\cursor_cext.py", line 356, in execute
    self._connection.cmd_query(
    ~~~~~~~~~~~~~~~~~~~~~~~~~~^
        self._stmt_partition["mappable_stmt"],
        ^^^^^^^^^^^^^^^^^^^^^^^^^^^^^^^^^^^^^^
    ...<2 lines>...
        raw_as_string=self._raw_as_string,
        ^^^^^^^^^^^^^^^^^^^^^^^^^^^^^^^^^^
    )
    ^
  File "C:\Users\mnarv\OneDrive\Desktop\ALL WORK\project_SQL+DB\.venv\Lib\site-packages\mysql\connector\opentelemetry\context_propagation.py", line 97, in wrapper
    return method(cnx, *args, **kwargs)
  File "C:\Users\mnarv\OneDrive\Desktop\ALL WORK\project_SQL+DB\.venv\Lib\site-packages\mysql\connector\connection_cext.py", line 781, in cmd_query
    raise get_mysql_exception(
        err.errno, msg=err.msg, sqlstate=err.sqlstate
    ) from err
mysql.connector.errors.ProgrammingError: 1054 (42S22): Unknown column 'cart_id' in 'where clause'
2025-07-22 14:02:16,662 - INFO - Product ID exists: 4
2025-07-22 14:02:38,308 - INFO - Product ID exists: 3
2025-07-22 14:02:38,316 - ERROR - Error updating cart item: 1054 (42S22): Unknown column 'cart_id' in 'where clause'
Traceback (most recent call last):
  File "C:\Users\mnarv\OneDrive\Desktop\ALL WORK\project_SQL+DB\.venv\Lib\site-packages\mysql\connector\connection_cext.py", line 772, in cmd_query
    self._cmysql.query(
    ~~~~~~~~~~~~~~~~~~^
        query,
        ^^^^^^
    ...<3 lines>...
        query_attrs=self.query_attrs,
        ^^^^^^^^^^^^^^^^^^^^^^^^^^^^^
    )
    ^
_mysql_connector.MySQLInterfaceError: Unknown column 'cart_id' in 'where clause'

The above exception was the direct cause of the following exception:

Traceback (most recent call last):
  File "C:\Users\mnarv\OneDrive\Desktop\ALL WORK\project_SQL+DB\model\cart_model.py", line 70, in update_to_cart
    cursor.execute("""
    ~~~~~~~~~~~~~~^^^^
        UPDATE cart_items
        ^^^^^^^^^^^^^^^^^
    ...<5 lines>...
        WHERE cart_id = %s
        ^^^^^^^^^^^^^^^^^^
    """, (quantity, size, color, quality, product_id, cart_id))
    ^^^^^^^^^^^^^^^^^^^^^^^^^^^^^^^^^^^^^^^^^^^^^^^^^^^^^^^^^^^
  File "C:\Users\mnarv\OneDrive\Desktop\ALL WORK\project_SQL+DB\.venv\Lib\site-packages\mysql\connector\cursor_cext.py", line 356, in execute
    self._connection.cmd_query(
    ~~~~~~~~~~~~~~~~~~~~~~~~~~^
        self._stmt_partition["mappable_stmt"],
        ^^^^^^^^^^^^^^^^^^^^^^^^^^^^^^^^^^^^^^
    ...<2 lines>...
        raw_as_string=self._raw_as_string,
        ^^^^^^^^^^^^^^^^^^^^^^^^^^^^^^^^^^
    )
    ^
  File "C:\Users\mnarv\OneDrive\Desktop\ALL WORK\project_SQL+DB\.venv\Lib\site-packages\mysql\connector\opentelemetry\context_propagation.py", line 97, in wrapper
    return method(cnx, *args, **kwargs)
  File "C:\Users\mnarv\OneDrive\Desktop\ALL WORK\project_SQL+DB\.venv\Lib\site-packages\mysql\connector\connection_cext.py", line 781, in cmd_query
    raise get_mysql_exception(
        err.errno, msg=err.msg, sqlstate=err.sqlstate
    ) from err
mysql.connector.errors.ProgrammingError: 1054 (42S22): Unknown column 'cart_id' in 'where clause'
2025-07-22 14:04:58,080 - INFO - Product ID exists: 4
2025-07-22 14:04:58,086 - ERROR - Error updating cart item: 1054 (42S22): Unknown column 'cart_id' in 'where clause'
Traceback (most recent call last):
  File "C:\Users\mnarv\OneDrive\Desktop\ALL WORK\project_SQL+DB\.venv\Lib\site-packages\mysql\connector\connection_cext.py", line 772, in cmd_query
    self._cmysql.query(
    ~~~~~~~~~~~~~~~~~~^
        query,
        ^^^^^^
    ...<3 lines>...
        query_attrs=self.query_attrs,
        ^^^^^^^^^^^^^^^^^^^^^^^^^^^^^
    )
    ^
_mysql_connector.MySQLInterfaceError: Unknown column 'cart_id' in 'where clause'

The above exception was the direct cause of the following exception:

Traceback (most recent call last):
  File "C:\Users\mnarv\OneDrive\Desktop\ALL WORK\project_SQL+DB\model\cart_model.py", line 70, in update_to_cart
    cursor.execute("""
    ~~~~~~~~~~~~~~^^^^
        UPDATE cart_items
        ^^^^^^^^^^^^^^^^^
    ...<5 lines>...
        WHERE cart_id = %s
        ^^^^^^^^^^^^^^^^^^
    """, (quantity, size, color, quality, product_id, cart_id))
    ^^^^^^^^^^^^^^^^^^^^^^^^^^^^^^^^^^^^^^^^^^^^^^^^^^^^^^^^^^^
  File "C:\Users\mnarv\OneDrive\Desktop\ALL WORK\project_SQL+DB\.venv\Lib\site-packages\mysql\connector\cursor_cext.py", line 356, in execute
    self._connection.cmd_query(
    ~~~~~~~~~~~~~~~~~~~~~~~~~~^
        self._stmt_partition["mappable_stmt"],
        ^^^^^^^^^^^^^^^^^^^^^^^^^^^^^^^^^^^^^^
    ...<2 lines>...
        raw_as_string=self._raw_as_string,
        ^^^^^^^^^^^^^^^^^^^^^^^^^^^^^^^^^^
    )
    ^
  File "C:\Users\mnarv\OneDrive\Desktop\ALL WORK\project_SQL+DB\.venv\Lib\site-packages\mysql\connector\opentelemetry\context_propagation.py", line 97, in wrapper
    return method(cnx, *args, **kwargs)
  File "C:\Users\mnarv\OneDrive\Desktop\ALL WORK\project_SQL+DB\.venv\Lib\site-packages\mysql\connector\connection_cext.py", line 781, in cmd_query
    raise get_mysql_exception(
        err.errno, msg=err.msg, sqlstate=err.sqlstate
    ) from err
mysql.connector.errors.ProgrammingError: 1054 (42S22): Unknown column 'cart_id' in 'where clause'
2025-07-22 14:06:05,621 - INFO - Product ID exists: 4
2025-07-22 14:06:58,885 - INFO - User found for email: aayanali1208@gmail.com
2025-07-22 14:12:42,266 - INFO - User found for email: aayanali1208@gmail.com
2025-07-22 14:19:24,243 - INFO - User found for email: aayanali1208@gmail.com
2025-07-22 14:19:24,246 - INFO - Product ID exists: 5
2025-07-22 14:19:49,380 - INFO - User found for email: aayanali1208@gmail.com
2025-07-22 14:19:49,885 - INFO - User ID found for email: aayanali1208@gmail.com
2025-07-22 14:20:01,385 - INFO - User found for email: aayanali1208@gmail.com
2025-07-22 14:20:01,388 - INFO - Product ID exists: 5
2025-07-22 14:20:46,359 - INFO - User found for email: aayanali1208@gmail.com
2025-07-22 14:23:09,352 - INFO - User found for email: aayanali1208@gmail.com
2025-07-22 14:24:47,514 - INFO - User found for email: aayanali1208@gmail.com
2025-07-22 14:24:47,518 - ERROR - No orders updated for order 49
2025-07-22 14:24:47,519 - ERROR - Error updating order address for order 49: Update failed
Traceback (most recent call last):
  File "C:\Users\mnarv\OneDrive\Desktop\ALL WORK\project_SQL+DB\model\order_model.py", line 150, in update_order_address_model
    raise Exception("Update failed")
Exception: Update failed
2025-07-22 14:24:59,878 - INFO - User found for email: aayanali1208@gmail.com
2025-07-22 14:24:59,894 - INFO - Order address updated for order 49
2025-07-22 14:27:25,802 - INFO - User found for email: aayanali1208@gmail.com
2025-07-22 14:27:26,430 - INFO - Product ID exists: 5
2025-07-22 14:27:26,468 - INFO - Order item updated for order 49 and inventory 5
2025-07-22 14:28:52,916 - INFO - User found for email: aayanali1208@gmail.com
2025-07-22 14:28:53,220 - INFO - Product ID exists: 1
2025-07-22 14:29:20,011 - INFO - User found for email: aayanali1208@gmail.com
2025-07-22 14:29:20,300 - INFO - Product ID exists: 1
2025-07-22 14:29:31,390 - INFO - User found for email: aayanali1208@gmail.com
2025-07-22 14:29:31,669 - INFO - Product ID exists: 1
2025-07-22 14:29:40,108 - INFO - User found for email: aayanali1208@gmail.com
2025-07-22 14:29:40,403 - INFO - Product ID exists: 1
2025-07-22 14:29:44,111 - INFO - User found for email: aayanali1208@gmail.com
2025-07-22 14:29:44,427 - INFO - Product ID exists: 1
2025-07-22 14:30:20,142 - INFO - User found for email: aayanali1208@gmail.com
2025-07-22 16:12:36,973 - INFO - User found for email: aayanali1208@gmail.com
2025-07-22 16:12:44,562 - INFO - User found for email: aayanali1208@gmail.com
2025-07-22 16:12:45,291 - INFO - User ID found for email: aayanali1208@gmail.com
2025-07-22 16:13:03,864 - INFO - User found for email: aayanali1208@gmail.com
2025-07-22 16:13:04,300 - INFO - Product ID exists: 4
2025-07-22 16:13:04,393 - INFO - Order item updated for order 48 and inventory 4
2025-07-22 16:13:37,250 - INFO - User found for email: aayanali1208@gmail.com
2025-07-22 16:13:37,740 - INFO - Product ID exists: 4
2025-07-22 16:13:37,781 - INFO - Order item updated for order 48 and inventory 4
2025-07-22 16:13:58,436 - INFO - User found for email: aayanali1208@gmail.com
2025-07-22 16:13:58,890 - INFO - Product ID exists: 4
2025-07-22 16:13:58,927 - INFO - Order item updated for order 48 and inventory 4
2025-07-22 16:14:20,981 - INFO - User found for email: aayanali1208@gmail.com
2025-07-22 16:14:21,384 - INFO - Product ID exists: 4
2025-07-22 16:14:21,415 - INFO - Order item updated for order 48 and inventory 4
2025-07-22 16:14:31,707 - INFO - User found for email: aayanali1208@gmail.com
2025-07-22 16:14:32,155 - INFO - Product ID exists: 4
2025-07-22 16:14:32,189 - INFO - Order item updated for order 48 and inventory 4
2025-07-22 16:15:25,753 - INFO - User found for email: aayanali1208@gmail.com
2025-07-22 16:15:26,149 - INFO - Product ID exists: 5
2025-07-22 16:16:11,351 - INFO - User found for email: aayanali1208@gmail.com
2025-07-22 16:16:11,770 - INFO - Product ID exists: 5
2025-07-22 16:16:13,158 - INFO - User found for email: aayanali1208@gmail.com
2025-07-22 16:16:13,696 - INFO - Product ID exists: 5
2025-07-22 16:16:39,108 - INFO - User found for email: aayanali1208@gmail.com
2025-07-22 16:16:39,449 - INFO - Product ID exists: 2
2025-07-22 16:18:41,318 - INFO - User found for email: aayanali1208@gmail.com
2025-07-22 16:29:53,063 - INFO - User found for email: aayanali1208@gmail.com
2025-07-22 16:29:53,064 - INFO - Product ID exists: 4
2025-07-22 16:30:49,586 - INFO - User found for email: aayanali1208@gmail.com
2025-07-22 16:32:19,246 - INFO - User found for email: aayanali1208@gmail.com
2025-07-22 16:32:43,394 - INFO - User found for email: aayanali1208@gmail.com
2025-07-22 16:35:09,721 - INFO - User found for email: aayanali1208@gmail.com
